Workbook

Sheet Planilha1
A6: Na Midola FC
A7: Shoji
A8: 46367
A9: -90.06
A10: -
A11: 0.00
A12: -1º
A18: AvantiPalestraFC
A19: Tiago Matias Dias
A20: 46367
A21: -82.25
A22: -
A23: 0.00
A24: -2º
A30: Real Rattaria FC
A31: Gabriel Ratto
A32: 46367
A33: -73.96
A34: -
A35: 0.00
A36: -3º
A42: Lanterninha Futebol Clube
A43: Robson Taglia
A44: 46366
A45: -73.45
A46: -
A47: 0.00
A48: -4º
A54: Borussia do Jaguaré
A55: Rogério Lagos
A56: 46368
A57: -72.35
A58: -
A59: 0.00
A60: -5º
A66: Luket Wanderes fc
A67: Lucas Silva Vieira
A68: 46367
A69: -68.36
A70: -
...

Sheet Planilha4
A1: A | B1: B
A2: Na Midola FC | B2: 1
A3: Shoji | B3: 2
A4: 46367 | B4: 3
A5: -90.06 | B5: 4
A6: - | B6: 5
A7: 0.00 | B7: 6
A8: -1º | B8: 7
B9: 8
B10: 9
B11: 10
B12: 11
B13: 12
A14: AvantiPalestraFC | B14: 1
A15: Tiago Matias Dias | B15: 2
A16: 46367 | B16: 3
A17: -82.25 | B17: 4
A18: - | B18: 5
A19: 0.00 | B19: 6
A20: -2º | B20: 7
B21: 8
B22: 9
B23: 10
B24: 11
B25: 12
A26: Real Rattaria FC | B26: 1
A27: Gabriel Ratto | B27: 2
A28: 46367 | B28: 3
A29: -73.96 | B29: 4
A30: - | B30: 5
A31: 0.00 | B31: 6
A32: -3º | B32: 7
B33: 8
B34: 9
B35: 10
B36: 11
B37: 12
A38: Lanterninha Futebol Clube | B38: 1
A39: Robson Taglia | B39: 2
A40: 46366 | B40: 3
...

Sheet Planilha8
A2: Nenenzico FC | L2: Bilao Sport Club
A3: Carlos Barbosa | L3: Gabriel Alencar
A4: 97.66 | L4: C$ 272.58
A5: 1º | L5: 1º
A6: Não Escalou | L6: Não Escalou
A7: Acessar o perfil do time Bilao Sport FC | L7: Acessar o perfil do time APELÕES FUTEBOL CLUB
A9: Bilao Sport FC | L9: APELÕES FUTEBOL CLUB
A10: Gabriel Alencar | L10: Greg Quirino
A11: 94.16 | L11: C$ 181.30
A12: 2º | L12: 2º
A13: Não Escalou | L13: Não Escalou
A14: Acessar o perfil do time FUCKER AND SUCKER FC | L14: Acessar o perfil do time Evans Jr FC
... A580: Não Escalou | L580: Não Escalou

Sheet Col Val
B1: c2 | E1: c2 | H1: c2 | K1: c2
A2: HPano FC | B2: 1 | D2: Bilao Sport Club | E2: 1 | G2: Nenenzico FC | H2: 1 | J2: Bilao Sport Club | K2: 1
A3: Henrique Panobianco | B3: 2 | D3: Gabriel Alencar | E3: 2 | G3: Carlos Barbosa | H3: 2 | J3: Gabriel Alencar | K3: 2
A4: 98.38 | B4: 3 | D4: C$ 266.09 | E4: 3 | G4: 97.66 | H4: 3 | J4: C$ 272.58 | K4: 3
A5: 1º | B5: 4 | D5: 1º | E5: 4 | G5: 1º | H5: 4 | J5: 1º | K5: 4
A6: Não Escalou | B6: 5 | D6: Não Escalou | E6: 5 | G6: Não Escalou | H6: 5 | J6: Não Escalou | K6: 5
A7: Acessar o perfil do time Centenario Alviverde | B7: 6 | D7: Acessar o perfil do time APELÕES FUTEBOL CLUB | E7: 6 | G7: Acessar o perfil do time Bilao Sport FC | H7: 6 | J7: Acessar o perfil do time APELÕES FUTEBOL CLUB | K7: 6
B8: 7 | E8: 7 | H8: 7 | K8: 7
A9: Centenario Alviverde | B9: 1 | D9: APELÕES FUTEBOL CLUB | E9: 1 | G9: Bilao Sport FC | H9: 1 | J9: APELÕES FUTEBOL CLUB | K9: 1
A10: Allan James | B10: 2 | D10: Greg Quirino | E10: 2 | G10: Gabriel Alencar | H10: 2 | J10: Greg Quirino | K10: 2
A11: 97.78 | B11: 3 | D11: C$ 179.31 | E11: 3 | G11: 94.16 | H11: 3 | J11: C$ 181.30 | K11: 3
A12: 2º | B12: 4 | D12: 2º | E12: 4 | G12: 2º | H12: 4 | J12: 2º | K12: 4
A13: Não Escalou | B13: 5 | D13: Não Escalou | E13: 5 | G13: Não Escalou | H13: 5 | J13: Não Escalou | K13: 5
A14: Acessar o perfil do time Botafogo Hell | B14: 6 | D14: Acessar o perfil do time Allejo Team F.C | E14: 6 | G14: Acessar o perfil do time FUCKER AND SUCKER FC | H14: 6 | J14: Acessar o perfil do time Evans Jr FC | K14: 6
B15: 7 | E15: 7 | H15: 7 | K15: 7
A16: Botafogo Hell | B16: 1 | D16: Allejo Team F.C | E16: 1 | G16: FUCKER AND SUCKER FC | H16: 1 | J16: Evans Jr FC | K16: 1
A17: Gabriel | B17: 2 | D17: Yuri Oliveira | E17: 2 | G17: Veron | H17: 2 | J17: Evanil Junior | K17: 2
A18: 97.68 | B18: 3 | D18: C$ 176.98 | E18: 3 | G18: 93.95 | H18: 3 | J18: C$ 174.24 | K18: 3
A19: 3º | B19: 4 | D19: 3º | E19: 4 | G19: 3º | H19: 4 | J19: 3º | K19: 4
A20: Não Escalou | B20: 5 | D20: Não Escalou | E20: 5 | G20: Não Escalou | H20: 5 | J20: Não Escalou | K20: 5
A21: Acessar o perfil do time CamisaNegra FC | B21: 6 | D21: Acessar o perfil do time Vuduzera | E21: 6 | G21: Acessar o perfil do time Botafogo Hell | H21: 6 | J21: Acessar o perfil do time AvantiPalestraFC | K21: 6
B22: 7 | E22: 7 | H22: 7 | K22: 7
A23: CamisaNegra FC | B23: 1 | D23: Vuduzera | E23: 1 | G23: Botafogo Hell | H23: 1 | J23: AvantiPalestraFC | K23: 1
A24: Lissão | B24: 2 | D24: Vudu | E24: 2 | G24: Gabriel | H24: 2 | J24: Tiago Matias Dias | K24: 2
A25: 96.30 | B25: 3 | D25: C$ 173.91 | E25: 3 | G25: 90.26 | H25: 3 | J25: C$ 173.69 | K25: 3
A26: 4º | B26: 4 | D26: 4º | E26: 4 | G26: 4º | H26: 4 | J26: 4º | K26: 4
A27: Não Escalou | B27: 5 | D27: Não Escalou | E27: 5 | G27: Escalou | H27: 5 | J27: Não Escalou | K27: 5
A28: Acessar o perfil do time Vuduzera | B28: 6 | D28: Acessar o perfil do time AvantiPalestraFC | E28: 6 | G28: Acessar o perfil do time Na Midola FC | H28: 6 | J28: Acessar o perfil do time Allejo Team F.C | K28: 6
B29: 7 | E29: 7 | H29: 7 | K29: 7
A30: Vuduzera | B30: 1 | D30: AvantiPalestraFC | E30: 1 | G30: Na Midola FC | H30: 1 | J30: Allejo Team F.C | K30: 1
A31: Vudu | B31: 2 | D31: Tiago Matias Dias | E31: 2 | G31: Shoji | H31: 2 | J31: Yuri Oliveira | K31: 2
A32: 95.75 | B32: 3 | D32: C$ 171.20 | E32: 3 | G32: 89.56 | H32: 3 | J32: C$ 173.61 | K32: 3
A33: 5º | B33: 4 | D33: 5º | E33: 4 | G33: 5º | H33: 4 | J33: 5º | K33: 4
A34: Não Escalou | B34: 5 | D34: Não Escalou | E34: 5 | G34: Não Escalou | H34: 5 | J34: Não Escalou | K34: 5
A35: Acessar o perfil do time Andrétero FC | B35: 6 | D35: Acessar o perfil do time Evans Jr FC | E35: 6 | G35: Acessar o perfil do time AvantiPalestraFC | H35: 6 | J35: Acessar o perfil do time Vuduzera | K35: 6
B36: 7 | E36: 7 | H36: 7 | K36: 7
A37: Andrétero FC | B37: 1 | D37: Evans Jr FC | E37: 1 | G37: AvantiPalestraFC | H37: 1 | J37: Vuduzera | K37: 1
A38: André Mendes | B38: 2 | D38: Evanil Junior | E38: 2 | G38: Tiago Matias Dias | H38: 2 | J38: Vudu | K38: 2
A39: 91.58 | B39: 3 | D39: C$ 170.73 | E39: 3 | G39: 89.36 | H39: 3 | J39: C$ 171.99 | K39: 3
A40: 6º | B40: 4 | D40: 6º | E40: 4 | G40: 6º | H40: 4 | J40: 6º | K40: 4
...

Sheet Colagem
A1: HPano FC | B1: 98.38 | D1: Bilao Sport Club | E1: C$ 266.09 | G1: Nenenzico FC | H1: 97.66 | J1: Bilao Sport Club | K1: C$ 272.58
A2: Centenario Alviverde | B2: 97.78 | D2: APELÕES FUTEBOL CLUB | E2: C$ 179.31 | G2: Bilao Sport FC | H2: 94.16 | J2: APELÕES FUTEBOL CLUB | K2: C$ 181.30
A3: Botafogo Hell | B3: 97.68 | D3: Allejo Team F.C | E3: C$ 176.98 | G3: FUCKER AND SUCKER FC | H3: 93.95 | J3: Evans Jr FC | K3: C$ 174.24
A4: CamisaNegra FC | B4: 96.30 | D4: Vuduzera | E4: C$ 173.91 | G4: Botafogo Hell | H4: 90.26 | J4: AvantiPalestraFC | K4: C$ 173.69
A5: Vuduzera | B5: 95.75 | D5: AvantiPalestraFC | E5: C$ 171.20 | G5: Na Midola FC | H5: 89.56 | J5: Allejo Team F.C | K5: C$ 173.61
A6: Andrétero FC | B6: 91.58 | D6: Evans Jr FC | E6: C$ 170.73 | G6: AvantiPalestraFC | H6: 89.36 | J6: Vuduzera | K6: C$ 171.99
A7: ZEKABOLEIRO | B7: 91.00 | D7: Metamoney F.C | E7: C$ 170.64 | G7: sccpguifc | H7: 86.25 | J7: Coxinha Prime | K7: C$ 170.37
A8: Real Rattaria FC | B8: 89.99 | D8: Centenario Alviverde | E8: C$ 170.31 | G8: Kings Futebol Club | H8: 85.06 | J8: LMD FC | K8: C$ 169.76
A9: Wedgol | B9: 88.80 | D9: LMD FC | E9: C$ 170.12 | G9: Real Rattaria FC | H9: 84.86 | J9: Metamoney F.C | K9: C$ 169.55
A10: Amigos do Loco Abreu | B10: 88.50 | D10: PALM£IRAS S.E.P. | E10: C$ 169.22 | G10: APELÕES FUTEBOL CLUB | H10: 83.36 | J10: Centenario Alviverde | K10: C$ 169.50
A11: Silasbrs FC | B11: 88.16 | D11: Coxinha Prime | E11: C$ 168.68 | G11: Evans Jr FC | H11: 83.26 | J11: Ipanema13 | K11: C$ 167.49
A12: BURZA10 F C | B12: 87.68 | D12: Ipanema13 | E12: C$ 168.58 | G12: CalazansTeam | H12: 82.76 | J12: Bilao Sport FC | K12: C$ 166.88
... A83: CR Pelég | B83: 12.30 | D83: CR Pelég | E83: C$ 89.85 | G83: CR Pelég | H83: 23.70 | J83: CR Pelég | K83: C$ 91.00

Sheet base_cod_2026
A1: cod | B1: time | C1: P | D1: pts | E1: c | F1: cart | G1: x | H1: ano | I1: rodada | J1: cartola_time_id | K1: pontos | L1: patrimonio | M1: posicao | N1: xx | O1: =CONCATENATE(H1,",",I1,",",J1,",",K1,",",L1,",",M1) -> ano,rodada,cartola_time_id,pontos,patrimonio,posicao
A2: 15 | B2: Nenenzico FC | C2: =VLOOKUP(B2,Colagem!G:H,2,FALSE) -> 97.66 | D2: =--SUBSTITUTE(C2, ".", ",") -> 97.66 | E2: =VLOOKUP(B2,Colagem!J:K,2,FALSE) -> C$ 165.12 | F2: =SUBSTITUTE(E2, "C$","") -> 165.12 | H2: 2026 | I2: 22 | J2: 15 | K2: =C2 -> 97.66 | L2: =TRIM(F2) -> 165.12 | M2: 1 | O2: =CONCATENATE(H2,",",I2,",",J2,",",K2,",",L2,",",M2) -> 2026,22,15,97.66,165.12,1
A3: 66 | B3: Bilao Sport FC | C3: =VLOOKUP(B3,Colagem!G:H,2,FALSE) -> 94.16 | D3: =--SUBSTITUTE(C3, ".", ",") -> 94.16 | E3: =VLOOKUP(B3,Colagem!J:K,2,FALSE) -> C$ 166.88 | F3: =SUBSTITUTE(E3, "C$","") -> 166.88 | H3: 2026 | I3: 22 | J3: 66 | K3: =C3 -> 94.16 | L3: =TRIM(F3) -> 166.88 | M3: 2 | O3: =CONCATENATE(H3,",",I3,",",J3,",",K3,",",L3,",",M3) -> 2026,22,66,94.16,166.88,2
A4: 62 | B4: FUCKER AND SUCKER FC | C4: =VLOOKUP(B4,Colagem!G:H,2,FALSE) -> 93.95 | D4: =--SUBSTITUTE(C4, ".", ",") -> 93.95 | E4: =VLOOKUP(B4,Colagem!J:K,2,FALSE) -> C$ 141.15 | F4: =SUBSTITUTE(E4, "C$","") -> 141.15 | H4: 2026 | I4: 22 | J4: 62 | K4: =C4 -> 93.95 | L4: =TRIM(F4) -> 141.15 | M4: 3 | O4: =CONCATENATE(H4,",",I4,",",J4,",",K4,",",L4,",",M4) -> 2026,22,62,93.95,141.15,3
A5: 24 | B5: Botafogo Hell | C5: =VLOOKUP(B5,Colagem!G:H,2,FALSE) -> 90.26 | D5: =--SUBSTITUTE(C5, ".", ",") -> 90.26 | E5: =VLOOKUP(B5,Colagem!J:K,2,FALSE) -> C$ 154.67 | F5: =SUBSTITUTE(E5, "C$","") -> 154.67 | H5: 2026 | I5: 22 | J5: 24 | K5: =C5 -> 90.26 | L5: =TRIM(F5) -> 154.67 | M5: 4 | O5: =CONCATENATE(H5,",",I5,",",J5,",",K5,",",L5,",",M5) -> 2026,22,24,90.26,154.67,4
A6: 77 | B6: Na Midola FC | C6: =VLOOKUP(B6,Colagem!G:H,2,FALSE) -> 89.56 | D6: =--SUBSTITUTE(C6, ".", ",") -> 89.56 | E6: =VLOOKUP(B6,Colagem!J:K,2,FALSE) -> C$ 159.20 | F6: =SUBSTITUTE(E6, "C$","") -> 159.20 | H6: 2026 | I6: 22 | J6: 77 | K6: =C6 -> 89.56 | L6: =TRIM(F6) -> 159.20 | M6: 5 | O6: =CONCATENATE(H6,",",I6,",",J6,",",K6,",",L6,",",M6) -> 2026,22,77,89.56,159.20,5
A7: 75 | B7: AvantiPalestraFC | C7: =VLOOKUP(B7,Colagem!G:H,2,FALSE) -> 89.36 | D7: =--SUBSTITUTE(C7, ".", ",") -> 89.36 | E7: =VLOOKUP(B7,Colagem!J:K,2,FALSE) -> C$ 173.69 | F7: =SUBSTITUTE(E7, "C$","") -> 173.69 | H7: 2026 | I7: 22 | J7: 75 | K7: =C7 -> 89.36 | L7: =TRIM(F7) -> 173.69 | M7: 6 | O7: =CONCATENATE(H7,",",I7,",",J7,",",K7,",",L7,",",M7) -> 2026,22,75,89.36,173.69,6
A8: 82 | B8: sccpguifc | C8: =VLOOKUP(B8,Colagem!G:H,2,FALSE) -> 86.25 | D8: =--SUBSTITUTE(C8, ".", ",") -> 86.25 | E8: =VLOOKUP(B8,Colagem!J:K,2,FALSE) -> C$ 145.92 | F8: =SUBSTITUTE(E8, "C$","") -> 145.92 | H8: 2026 | I8: 22 | J8: 82 | K8: =C8 -> 86.25 | L8: =TRIM(F8) -> 145.92 | M8: 7 | O8: =CONCATENATE(H8,",",I8,",",J8,",",K8,",",L8,",",M8) -> 2026,22,82,86.25,145.92,7
A9: 40 | B9: Kings Futebol Club | C9: =VLOOKUP(B9,Colagem!G:H,2,FALSE) -> 85.06 | D9: =--SUBSTITUTE(C9, ".", ",") -> 85.06 | E9: =VLOOKUP(B9,Colagem!J:K,2,FALSE) -> C$ 158.87 | F9: =SUBSTITUTE(E9, "C$","") -> 158.87 | H9: 2026 | I9: 22 | J9: 40 | K9: =C9 -> 85.06 | L9: =TRIM(F9) -> 158.87 | M9: 8 | O9: =CONCATENATE(H9,",",I9,",",J9,",",K9,",",L9,",",M9) -> 2026,22,40,85.06,158.87,8
A10: 68 | B10: Real Rattaria FC | C10: =VLOOKUP(B10,Colagem!G:H,2,FALSE) -> 84.86 | D10: =--SUBSTITUTE(C10, ".", ",") -> 84.86 | E10: =VLOOKUP(B10,Colagem!J:K,2,FALSE) -> C$ 155.32 | F10: =SUBSTITUTE(E10, "C$","") -> 155.32 | H10: 2026 | I10: 22 | J10: 68 | K10: =C10 -> 84.86 | L10: =TRIM(F10) -> 155.32 | M10: 9 | O10: =CONCATENATE(H10,",",I10,",",J10,",",K10,",",L10,",",M10) -> 2026,22,68,84.86,155.32,9
A11: 25 | B11: APELÕES FUTEBOL CLUB | C11: =VLOOKUP(B11,Colagem!G:H,2,FALSE) -> 83.36 | D11: =--SUBSTITUTE(C11, ".", ",") -> 83.36 | E11: =VLOOKUP(B11,Colagem!J:K,2,FALSE) -> C$ 181.30 | F11: =SUBSTITUTE(E11, "C$","") -> 181.30 | H11: 2026 | I11: 22 | J11: 25 | K11: =C11 -> 83.36 | L11: =TRIM(F11) -> 181.30 | M11: 10 | O11: =CONCATENATE(H11,",",I11,",",J11,",",K11,",",L11,",",M11) -> 2026,22,25,83.36,181.30,10
A12: 23 | B12: Evans Jr FC | C12: =VLOOKUP(B12,Colagem!G:H,2,FALSE) -> 83.26 | D12: =--SUBSTITUTE(C12, ".", ",") -> 83.26 | E12: =VLOOKUP(B12,Colagem!J:K,2,FALSE) -> C$ 174.24 | F12: =SUBSTITUTE(E12, "C$","") -> 174.24 | H12: 2026 | I12: 22 | J12: 23 | K12: =C12 -> 83.26 | L12: =TRIM(F12) -> 174.24 | M12: 11 | O12: =CONCATENATE(H12,",",I12,",",J12,",",K12,",",L12,",",M12) -> 2026,22,23,83.26,174.24,11
A13: 9 | B13: CalazansTeam | C13: =VLOOKUP(B13,Colagem!G:H,2,FALSE) -> 82.76 | D13: =--SUBSTITUTE(C13, ".", ",") -> 82.76 | E13: =VLOOKUP(B13,Colagem!J:K,2,FALSE) -> C$ 153.94 | F13: =SUBSTITUTE(E13, "C$","") -> 153.94 | H13: 2026 | I13: 22 | J13: 9 | K13: =C13 -> 82.76 | L13: =TRIM(F13) -> 153.94 | M13: 12 | O13: =CONCATENATE(H13,",",I13,",",J13,",",K13,",",L13,",",M13) -> 2026,22,9,82.76,153.94,12
... A84: 29 | B84: CR Pelég | C84: =VLOOKUP(B84,Colagem!G:H,2,FALSE) -> 23.70 | D84: =--SUBSTITUTE(C84, ".", ",") -> 23.7 | E84: =VLOOKUP(B84,Colagem!J:K,2,FALSE) -> C$ 91.00 | F84: =SUBSTITUTE(E84, "C$","") -> 91.00 | H84: 2026 | I84: 22 | J84: 29 | K84: =C84 -> 23.70 | L84: =TRIM(F84) -> 91.00 | M84: 83 | O84: =CONCATENATE(H84,",",I84,",",J84,",",K84,",",L84,",",M84) -> 2026,22,29,23.70,91.00,83

Sheet Planilha2
A1: a | B1: b
A2: ZAGO PRATIS FC | B2: 1 | E2: ZAGO PRATIS FC | G2: ZAGO PRATIS FC | H2: 1
A3: ANDRE PRATS | B3: 2 | E3: ANDRE PRATS | G3: ANDRE PRATS | H3: 2
A4: - | B4: 3 | E4: - | G4: - | H4: 3
A5: - | B5: 4 | E5: - | G5: - | H5: 4
A6: Não Escalou | B6: 5 | E6: Não Escalou | G6: Escalou | H6: 5
A7: Acessar o perfil do time Luket Wanderes fc | B7: 6 | E7: Acessar o perfil do time Luket Wanderes fc | G7: Acessar o perfil do time Luket Wanderes fc | H7: 6
B8: 7 | H8: 7
A9: Luket Wanderes fc | B9: 1 | E9: Luket Wanderes fc | G9: Luket Wanderes fc | H9: 1
A10: Lucas Silva Vieira | B10: 2 | E10: Lucas Silva Vieira | G10: Lucas Silva Vieira | H10: 2
A11: - | B11: 3 | E11: - | G11: - | H11: 3
A12: - | B12: 4 | E12: - | G12: - | H12: 4
A13: Não Escalou | B13: 5 | E13: Não Escalou | G13: Escalou | H13: 5
A14: Acessar o perfil do time FOI O QUE SOBROU | B14: 6 | E14: Acessar o perfil do time FOI O QUE SOBROU | G14: Acessar o perfil do time FOI O QUE SOBROU | H14: 6
B15: 7 | H15: 7
A16: FOI O QUE SOBROU | B16: 1 | E16: FOI O QUE SOBROU | G16: FOI O QUE SOBROU | H16: 1
A17: V. ÉDIPO | B17: 2 | E17: V. ÉDIPO | G17: V. ÉDIPO | H17: 2
A18: - | B18: 3 | E18: - | G18: - | H18: 3
A19: - | B19: 4 | E19: - | G19: - | H19: 4
A20: Escalou | B20: 5 | E20: Escalou | G20: Escalou | H20: 5
A21: Acessar o perfil do time CalazansTeam | B21: 6 | E21: Acessar o perfil do time CalazansTeam | G21: Acessar o perfil do time CalazansTeam | H21: 6
B22: 7 | H22: 7
A23: CalazansTeam | B23: 1 | E23: CalazansTeam | G23: CalazansTeam | H23: 1
A24: ALYSON | B24: 2 | E24: ALYSON | G24: ALYSON | H24: 2
A25: - | B25: 3 | E25: - | G25: - | H25: 3
A26: - | B26: 4 | E26: - | G26: - | H26: 4
A27: Não Escalou | B27: 5 | E27: Não Escalou | G27: Escalou | H27: 5
A28: Acessar o perfil do time CRPELUSO | B28: 6 | E28: Acessar o perfil do time CRPELUSO | G28: Acessar o perfil do time CRPELUSO | H28: 6
B29: 7 | H29: 7
A30: CRPELUSO | B30: 1 | E30: CRPELUSO | G30: CRPELUSO | H30: 1
A31: Claudio R Peluso | B31: 2 | E31: Claudio R Peluso | G31: Claudio R Peluso | H31: 2
A32: - | B32: 3 | E32: - | G32: - | H32: 3
A33: - | B33: 4 | E33: - | G33: - | H33: 4
A34: Escalou | B34: 5 | E34: Escalou | G34: Escalou | H34: 5
A35: Acessar o perfil do time PALM£IRAS S.E.P. | B35: 6 | E35: Acessar o perfil do time PALM£IRAS S.E.P. | G35: Acessar o perfil do time PALM£IRAS S.E.P. | H35: 6
B36: 7 | H36: 7
A37: PALM£IRAS S.E.P. | B37: 1 | E37: PALM£IRAS S.E.P. | G37: PALM£IRAS S.E.P. | H37: 1
A38: Diego Longo | B38: 2 | E38: Diego Longo | G38: Diego Longo | H38: 2
A39: - | B39: 3 | E39: - | G39: - | H39: 3
A40: - | B40: 4 | E40: - | G40: - | H40: 4
...

Sheet Planilha3
A1: Maletinhas F.C. | B1: X | C1: =VLOOKUP(A1,E:G,3,FALSE) -> Y | E1: ZAGO PRATIS FC | F1: =VLOOKUP(E1,A:B,2,FALSE) -> X | G1: Y
A2: Sobottka FC 633 | B2: X | C2: =VLOOKUP(A2,E:G,3,FALSE) -> Y | E2: Luket Wanderes fc | F2: =VLOOKUP(E2,A:B,2,FALSE) -> X | G2: Y
A3: GIGANTES MORUMBI F.C | B3: X | C3: =VLOOKUP(A3,E:G,3,FALSE) -> Y | E3: FOI O QUE SOBROU | F3: =VLOOKUP(E3,A:B,2,FALSE) -> X | G3: Y
A4: Adshow17 F.C | B4: X | C4: =VLOOKUP(A4,E:G,3,FALSE) -> Y | E4: CalazansTeam | F4: =VLOOKUP(E4,A:B,2,FALSE) -> X | G4: Y
A5: Schuletroll | B5: X | C5: =VLOOKUP(A5,E:G,3,FALSE) -> Y | E5: CRPELUSO | F5: =VLOOKUP(E5,A:B,2,FALSE) -> X | G5: Y
A6: CamisaNegra FC | B6: X | C6: =VLOOKUP(A6,E:G,3,FALSE) -> Y | E6: PALM£IRAS S.E.P. | F6: =VLOOKUP(E6,A:B,2,FALSE) -> X | G6: Y
A7: Mitinga`s F.C | B7: X | C7: =VLOOKUP(A7,E:G,3,FALSE) -> Y | E7: Bike Cristo | F7: =VLOOKUP(E7,A:B,2,FALSE) -> X | G7: Y
A8: FOI O QUE SOBROU | B8: X | C8: =VLOOKUP(A8,E:G,3,FALSE) -> Y | E8: Ferrugem Ultimate | F8: =VLOOKUP(E8,A:B,2,FALSE) -> X | G8: Y
A9: Vuduzera | B9: X | C9: =VLOOKUP(A9,E:G,3,FALSE) -> Y | E9: E.C. Ocram 5.6 | F9: =VLOOKUP(E9,A:B,2,FALSE) -> X | G9: Y
A10: ZEKABOLEIRO | B10: X | C10: =VLOOKUP(A10,E:G,3,FALSE) -> Y | E10: Maletinhas F.C. | F10: =VLOOKUP(E10,A:B,2,FALSE) -> X | G10: Y
A11: EmesuShow Porcolino | B11: X | C11: =VLOOKUP(A11,E:G,3,FALSE) -> Y | E11: 08 Ratto FC | F11: =VLOOKUP(E11,A:B,2,FALSE) -> X | G11: Y
A12: TIMAO R.F.G | B12: X | C12: =VLOOKUP(A12,E:G,3,FALSE) -> Y | E12: Real Rattaria FC | F12: =VLOOKUP(E12,A:B,2,FALSE) -> X | G12: Y
... A80: Lanterninha Futebol Clube | B80: X | C80: =VLOOKUP(A80,E:G,3,FALSE) -> Y | E80: A D Peaky Blinders | F80: =VLOOKUP(E80,A:B,2,FALSE) -> #N/A | G80: Y

Sheet ORG
A1: TIME | B1: CARTOLEIRO | C1: ORD | D1: ID | E1: nome | F1: ID | G1: X | H1: ID_time | I1: ID_CART | J1: NOME_TIME | K1: TEMPORADA | L1: DIV 2025 | M1: pos | N1: st | O1: DIV 2026 P | P1: DIV 2026 D | Q1: status[ | R1: X | S1: id_d | T1: time_id | U1: divisao_id | V1: temp | W1: ativo | Y1: id_fk | Z1: apelido | AA1: telefone | AB1: time coracao | AC1: cidade | AD1: estado | AE1: pais
A2: Maletinhas F.C. | B2: Ricardo | C2: 2 | E2: R MALETA | F2: 41 | H2: 41 | I2: 41 | J2: Maletinhas F.C. | K2: 2026 | L2: =VLOOKUP(J2,SERIES!B:K,10,FALSE) -> A | M2: =VLOOKUP(J2,SERIES!B:K,2,FALSE) -> 1 | N2: =VLOOKUP(J2,SERIES!B:K,9,FALSE) -> C | O2: A | P2: A | Q2: 2025 | T2: =H2 -> 41 | U2: 1 | V2: 2026 | W2: true
A3: Sobottka FC 633 | B3: Gustavo Sobottka | C3: 2 | E3: G SOBOTTKA | F3: 26 | H3: 26 | I3: 26 | J3: Sobottka FC 633 | K3: 2026 | L3: =VLOOKUP(J3,SERIES!B:K,10,FALSE) -> A | M3: =VLOOKUP(J3,SERIES!B:K,2,FALSE) -> 2 | N3: =VLOOKUP(J3,SERIES!B:K,9,FALSE) -> M | O3: A | P3: A | Q3: 2025 | T3: =H3 -> 26 | U3: 1 | V3: 2026 | W3: true
A4: GIGANTES MORUMBI F.C | B4: Sergio Garcia | C4: 2 | E4: S GARCIA | F4: 44 | H4: 44 | I4: 44 | J4: GIGANTES MORUMBI F.C | K4: 2026 | L4: =VLOOKUP(J4,SERIES!B:K,10,FALSE) -> A | M4: =VLOOKUP(J4,SERIES!B:K,2,FALSE) -> 3 | N4: =VLOOKUP(J4,SERIES!B:K,9,FALSE) -> M | O4: A | P4: A | Q4: 2025 | T4: =H4 -> 44 | U4: 1 | V4: 2026 | W4: true
A5: Adshow17 F.C | B5: Adson Mendes | C5: 2 | E5: ADSON | F5: 3 | H5: 3 | I5: 3 | J5: Adshow17 F.C | K5: 2026 | L5: =VLOOKUP(J5,SERIES!B:K,10,FALSE) -> A | M5: =VLOOKUP(J5,SERIES!B:K,2,FALSE) -> 4 | N5: =VLOOKUP(J5,SERIES!B:K,9,FALSE) -> M | O5: A | P5: A | Q5: 2025 | T5: =H5 -> 3 | U5: 1 | V5: 2026 | W5: true
A6: Schuletroll | B6: Leandro Schulai | C6: 6 | E6: SCHULETA | F6: 67 | H6: 70 | I6: 67 | J6: Schuletroll | K6: 2026 | L6: =VLOOKUP(J6,SERIES!B:K,10,FALSE) -> A | M6: =VLOOKUP(J6,SERIES!B:K,2,FALSE) -> 5 | N6: =VLOOKUP(J6,SERIES!B:K,9,FALSE) -> M | O6: A | P6: A | Q6: 2025 | T6: =H6 -> 70 | U6: 1 | V6: 2026 | W6: true
A7: CamisaNegra FC | B7: Lissão | C7: 2 | E7: LISSAO | F7: 32 | H7: 32 | I7: 32 | J7: CamisaNegra FC | K7: 2026 | L7: A | M7: 6 | N7: M | O7: A | P7: A | Q7: 2025 | T7: =H7 -> 32 | U7: 1 | V7: 2026 | W7: true
A8: Mitinga`s F.C | B8: Marcel Cantalego | C8: 2 | E8: M CANTALEGO | F8: 37 | H8: 37 | I8: 37 | J8: Mitinga`s F.C | K8: 2026 | L8: =VLOOKUP(J8,SERIES!B:K,10,FALSE) -> A | M8: =VLOOKUP(J8,SERIES!B:K,2,FALSE) -> 7 | N8: =VLOOKUP(J8,SERIES!B:K,9,FALSE) -> M | O8: A | P8: A | Q8: 2025 | T8: =H8 -> 37 | U8: 1 | V8: 2026 | W8: true
A9: FOI O QUE SOBROU | B9: V. ÉDIPO | C9: 2 | E9: EDIPO | F9: 47 | H9: 47 | I9: 47 | J9: FOI O QUE SOBROU | K9: 2026 | L9: =VLOOKUP(J9,SERIES!B:K,10,FALSE) -> A | M9: =VLOOKUP(J9,SERIES!B:K,2,FALSE) -> 8 | N9: =VLOOKUP(J9,SERIES!B:K,9,FALSE) -> M | O9: A | P9: A | Q9: 2025 | T9: =H9 -> 47 | U9: 1 | V9: 2026 | W9: true
A10: Vuduzera | B10: Vudu | C10: 2 | E10: VUDU | F10: 63 | H10: 63 | I10: 63 | J10: Vuduzera | K10: 2026 | L10: =VLOOKUP(J10,SERIES!B:K,10,FALSE) -> A | M10: =VLOOKUP(J10,SERIES!B:K,2,FALSE) -> 9 | N10: =VLOOKUP(J10,SERIES!B:K,9,FALSE) -> M | O10: A | P10: A | Q10: 2025 | T10: =H10 -> 63 | U10: 1 | V10: 2026 | W10: true
A11: ZEKABOLEIRO | B11: TRIPA | C11: 2 | E11: R TRIPAO | F11: 61 | H11: 61 | I11: 61 | J11: ZEKABOLEIRO | K11: 2026 | L11: =VLOOKUP(J11,SERIES!B:K,10,FALSE) -> A | M11: =VLOOKUP(J11,SERIES!B:K,2,FALSE) -> 10 | N11: =VLOOKUP(J11,SERIES!B:K,9,FALSE) -> M | O11: A | P11: A | Q11: 2025 | T11: =H11 -> 61 | U11: 1 | V11: 2026 | W11: true
A12: EmesuShow Porcolino | B12: Emerson Rocha | C12: 2 | E12: PORCOLINO | F12: 53 | H12: 53 | I12: 53 | J12: EmesuShow Porcolino | K12: 2026 | L12: =VLOOKUP(J12,SERIES!B:K,10,FALSE) -> A | M12: =VLOOKUP(J12,SERIES!B:K,2,FALSE) -> 12 | N12: =VLOOKUP(J12,SERIES!B:K,9,FALSE) -> M | O12: A | P12: A | Q12: 2025 | T12: =H12 -> 53 | U12: 1 | V12: 2026 | W12: true
A13: TIMAO R.F.G | B13: ROBSON CUNHA | C13: 2 | E13: R CUNHA | F13: 43 | H13: 43 | I13: 43 | J13: TIMAO R.F.G | K13: 2026 | L13: A | M13: 13 | N13: M | O13: A | P13: A | Q13: 2025 | T13: =H13 -> 43 | U13: 1 | V13: 2026 | W13: true
A14: PALM£IRAS S.E.P. | B14: Diego Longo | C14: 2 | E14: D LONGO | F14: 18 | H14: 18 | I14: 18 | J14: PALM£IRAS S.E.P. | K14: 2026 | L14: A | M14: 14 | N14: M | O14: A | P14: A | Q14: 2025 | T14: =H14 -> 18 | U14: 1 | V14: 2026 | W14: true
A15: ZAGO PRATIS FC | B15: ANDRE PRATS | C15: 1 | E15: PRATIS | F15: 1 | H15: 1 | I15: 1 | J15: ZAGO PRATIS FC | K15: 2026 | L15: A | M15: 16 | N15: M | O15: A | P15: A | Q15: 2025 | T15: =H15 -> 1 | U15: 1 | V15: 2026 | W15: true
A16: Luket Wanderes fc | B16: Lucas Silva Vieira | C16: 2 | E16: LUKET | F16: 35 | H16: 35 | I16: 35 | J16: Luket Wanderes fc | K16: 2026 | L16: =VLOOKUP(J16,SERIES!B:K,10,FALSE) -> B | M16: =VLOOKUP(J16,SERIES!B:K,2,FALSE) -> 21 | N16: =VLOOKUP(J16,SERIES!B:K,9,FALSE) -> P | O16: A | P16: A | Q16: 2025 | T16: =H16 -> 35 | U16: 1 | V16: 2026 | W16: true
A17: Amigos do Loco Abreu | B17: Ricardo Filgueiras | C17: 2 | E17: R FILGUEIRAS | F17: 42 | H17: 42 | I17: 42 | J17: Amigos do Loco Abreu | K17: 2026 | L17: =VLOOKUP(J17,SERIES!B:K,10,FALSE) -> B | M17: =VLOOKUP(J17,SERIES!B:K,2,FALSE) -> 22 | N17: =VLOOKUP(J17,SERIES!B:K,9,FALSE) -> P | O17: A | P17: A | Q17: 2025 | T17: =H17 -> 42 | U17: 1 | V17: 2026 | W17: true
A18: Metamoney F.C | B18: Marcio Vieira | C18: 2 | E18: M VIEIRA | F18: 38 | H18: 38 | I18: 38 | J18: Metamoney F.C | K18: 2026 | L18: =VLOOKUP(J18,SERIES!B:K,10,FALSE) -> B | M18: =VLOOKUP(J18,SERIES!B:K,2,FALSE) -> 23 | N18: =VLOOKUP(J18,SERIES!B:K,9,FALSE) -> P | O18: A | P18: A | Q18: 2025 | T18: =H18 -> 38 | U18: 1 | V18: 2026 | W18: true
A19: Silasbrs FC | B19: Silas Siqueira | C19: 2 | E19: S SIQUEIRA | F19: 45 | H19: 45 | I19: 45 | J19: Silasbrs FC | K19: 2026 | L19: =VLOOKUP(J19,SERIES!B:K,10,FALSE) -> B | M19: =VLOOKUP(J19,SERIES!B:K,2,FALSE) -> 24 | N19: =VLOOKUP(J19,SERIES!B:K,9,FALSE) -> P | O19: A | P19: A | Q19: 2025 | T19: =H19 -> 45 | U19: 1 | V19: 2026 | W19: true
A20: Os Porko é Loko - Z/O | B20: Anderson Nogueira | C20: 2 | E20: A NOGUEIRA | F20: 10 | H20: 10 | I20: 10 | J20: Os Porko é Loko - Z/O | K20: 2026 | L20: =VLOOKUP(J20,SERIES!B:K,10,FALSE) -> B | M20: =VLOOKUP(J20,SERIES!B:K,2,FALSE) -> 25 | N20: =VLOOKUP(J20,SERIES!B:K,9,FALSE) -> M | O20: B | P20: A | Q20: 2025 | T20: =H20 -> 10 | U20: 1 | V20: 2026 | W20: true
A21: CRPELUSO | B21: Claudio R Peluso | C21: 2 | E21: C PELUSO | F21: 17 | H21: 17 | I21: 17 | J21: CRPELUSO | K21: 2026 | L21: =VLOOKUP(J21,SERIES!B:K,10,FALSE) -> B | M21: =VLOOKUP(J21,SERIES!B:K,2,FALSE) -> 26 | N21: =VLOOKUP(J21,SERIES!B:K,9,FALSE) -> M | O21: B | P21: A | Q21: 2025 | T21: =H21 -> 17 | U21: 1 | V21: 2026 | W21: true
A22: Ipanema13 | B22: Alexandre Carlos | C22: 2 | E22: ALE CHINELO | F22: 5 | H22: 5 | I22: 5 | J22: Ipanema13 | K22: 2026 | L22: =VLOOKUP(J22,SERIES!B:K,10,FALSE) -> A | M22: =VLOOKUP(J22,SERIES!B:K,2,FALSE) -> 17 | N22: =VLOOKUP(J22,SERIES!B:K,9,FALSE) -> R | O22: B | P22: B | Q22: 2025 | T22: =H22 -> 5 | U22: 2 | V22: 2026 | W22: true
A23: OtoPat@ma | B23: Paulo | C23: 2 | E23: P OTO | F23: 57 | H23: 57 | I23: 57 | J23: OtoPat@ma | K23: 2026 | L23: =VLOOKUP(J23,SERIES!B:K,10,FALSE) -> A | M23: =VLOOKUP(J23,SERIES!B:K,2,FALSE) -> 18 | N23: =VLOOKUP(J23,SERIES!B:K,9,FALSE) -> R | O23: B | P23: B | Q23: 2025 | T23: =H23 -> 57 | U23: 2 | V23: 2026 | W23: true
A24: Brabo Globetrotters | B24: Eduardo Brabo | C24: 2 | E24: BRABO | F24: 21 | H24: 21 | I24: 21 | J24: Brabo Globetrotters | K24: 2026 | L24: =VLOOKUP(J24,SERIES!B:K,10,FALSE) -> A | M24: =VLOOKUP(J24,SERIES!B:K,2,FALSE) -> 19 | N24: =VLOOKUP(J24,SERIES!B:K,9,FALSE) -> R | O24: B | P24: B | Q24: 2025 | T24: =H24 -> 21 | U24: 2 | V24: 2026 | W24: true
A25: Abóbora Futebol C | B25: Wellyngton Remesso | C25: 2 | E25: Abobora | F25: 69 | H25: 74 | I25: 69 | J25: Abóbora Futebol C | K25: 2026 | L25: =VLOOKUP(J25,SERIES!B:K,10,FALSE) -> A | M25: 20 | N25: =VLOOKUP(J25,SERIES!B:K,9,FALSE) -> R | O25: B | P25: B | Q25: 2025 | T25: =H25 -> 74 | U25: 2 | V25: 2026 | W25: true
A26: Sempre ForteF.C. | B26: Jonathan Oliveira de | C26: 2 | E26: BATATA | F26: 30 | H26: 30 | I26: 30 | J26: Sempre ForteF.C. | K26: 2026 | L26: =VLOOKUP(J26,SERIES!B:K,10,FALSE) -> B | M26: =VLOOKUP(J26,SERIES!B:K,2,FALSE) -> 27 | N26: =VLOOKUP(J26,SERIES!B:K,9,FALSE) -> M | O26: B | P26: B | Q26: 2025 | T26: =H26 -> 30 | U26: 2 | V26: 2026 | W26: true
A27: Ferrugem Ultimate | B27: Thiago Ribas | C27: 2 | E27: T RIBAS | F27: 46 | H27: 46 | I27: 46 | J27: Ferrugem Ultimate | K27: 2026 | L27: =VLOOKUP(J27,SERIES!B:K,10,FALSE) -> B | M27: =VLOOKUP(J27,SERIES!B:K,2,FALSE) -> 28 | N27: =VLOOKUP(J27,SERIES!B:K,9,FALSE) -> M | O27: B | P27: B | Q27: 2025 | T27: =H27 -> 46 | U27: 2 | V27: 2026 | W27: true
A28: 08 Ratto FC | B28: Gabriel Ratto2 | C28: 5 | E28: G RATTO | F28: 66 | H28: 69 | I28: 66 | J28: 08 Ratto FC | K28: 2026 | L28: =VLOOKUP(J28,SERIES!B:K,10,FALSE) -> B | M28: =VLOOKUP(J28,SERIES!B:K,2,FALSE) -> 29 | N28: =VLOOKUP(J28,SERIES!B:K,9,FALSE) -> M | O28: B | P28: B | Q28: 2025 | T28: =H28 -> 69 | U28: 2 | V28: 2026 | W28: true
A29: GEJA | B29: Wedgol | C29: 3 | E29: WED | F29: 64 | H29: 64 | I29: 64 | J29: GEJA | K29: 2026 | L29: =VLOOKUP(J29,SERIES!B:K,10,FALSE) -> B | M29: =VLOOKUP(J29,SERIES!B:K,2,FALSE) -> 30 | N29: =VLOOKUP(J29,SERIES!B:K,9,FALSE) -> M | O29: B | P29: B | Q29: 2025 | T29: =H29 -> 64 | U29: 2 | V29: 2026 | W29: true
A30: FUCKER AND SUCKER FC | B30: Veron | C30: 2 | E30: VERON | F30: 62 | H30: 62 | I30: 62 | J30: FUCKER AND SUCKER FC | K30: 2026 | L30: =VLOOKUP(J30,SERIES!B:K,10,FALSE) -> B | M30: =VLOOKUP(J30,SERIES!B:K,2,FALSE) -> 32 | N30: =VLOOKUP(J30,SERIES!B:K,9,FALSE) -> M | O30: B | P30: B | Q30: 2025 | T30: =H30 -> 62 | U30: 2 | V30: 2026 | W30: true
A31: SC Ornaghi Paulista | B31: Eduardo Ribas | C31: 2 | E31: ORNAGHI | F31: 22 | H31: 22 | I31: 22 | J31: SC Ornaghi Paulista | K31: 2026 | L31: =VLOOKUP(J31,SERIES!B:K,10,FALSE) -> B | M31: =VLOOKUP(J31,SERIES!B:K,2,FALSE) -> 33 | N31: =VLOOKUP(J31,SERIES!B:K,9,FALSE) -> M | O31: B | P31: B | Q31: 2025 | T31: =H31 -> 22 | U31: 2 | V31: 2026 | W31: true
A32: Massiminismo FC | B32: Lucas Massimini | C32: 2 | E32: L MASSIMINI | F32: 33 | H32: 33 | I32: 33 | J32: Massiminismo FC | K32: 2026 | L32: =VLOOKUP(J32,SERIES!B:K,10,FALSE) -> B | M32: =VLOOKUP(J32,SERIES!B:K,2,FALSE) -> 35 | N32: =VLOOKUP(J32,SERIES!B:K,9,FALSE) -> M | O32: B | P32: B | Q32: 2025 | T32: =H32 -> 33 | U32: 2 | V32: 2026 | W32: true
A33: Bilao Sport Club | B33: Gabriel Alencar | C33: 4 | E33: G ALENCAR | F33: 65 | H33: 67 | I33: 65 | J33: Bilao Sport Club | K33: 2026 | L33: =VLOOKUP(J33,SERIES!B:K,10,FALSE) -> B | M33: =VLOOKUP(J33,SERIES!B:K,2,FALSE) -> 36 | N33: =VLOOKUP(J33,SERIES!B:K,9,FALSE) -> M | O33: B | P33: B | Q33: 2025 | T33: =H33 -> 67 | U33: 2 | V33: 2026 | W33: true
A34: Botafogo Hell | B34: Gabriel | C34: 2 | E34: G BOTAFOGO | F34: 24 | H34: 24 | I34: 24 | J34: Botafogo Hell | K34: 2026 | L34: =VLOOKUP(J34,SERIES!B:K,10,FALSE) -> C | M34: =VLOOKUP(J34,SERIES!B:K,2,FALSE) -> 41 | N34: =VLOOKUP(J34,SERIES!B:K,9,FALSE) -> P | O34: B | P34: B | Q34: 2025 | T34: =H34 -> 24 | U34: 2 | V34: 2026 | W34: true
A35: Bike Cristo | B35: Maurício Silva | C35: 2 | E35: VEIO DA LARANJA | F35: 39 | H35: 39 | I35: 39 | J35: Bike Cristo | K35: 2026 | L35: =VLOOKUP(J35,SERIES!B:K,10,FALSE) -> C | M35: =VLOOKUP(J35,SERIES!B:K,2,FALSE) -> 42 | N35: =VLOOKUP(J35,SERIES!B:K,9,FALSE) -> P | O35: B | P35: B | Q35: 2025 | T35: =H35 -> 39 | U35: 2 | V35: 2026 | W35: true
A36: J.V.Finhani | B36: Jefferson Finhani | C36: 2 | E36: J FINHANI | F36: 28 | H36: 28 | I36: 28 | J36: J.V.Finhani | K36: 2026 | L36: =VLOOKUP(J36,SERIES!B:K,10,FALSE) -> C | M36: =VLOOKUP(J36,SERIES!B:K,2,FALSE) -> 43 | N36: =VLOOKUP(J36,SERIES!B:K,9,FALSE) -> P | O36: B | P36: B | Q36: 2025 | T36: =H36 -> 28 | U36: 2 | V36: 2026 | W36: true
A37: Adriano ZIZU | B37: Adriano Monteiro | C37: 2 | E37: A ZIZU | F37: 2 | H37: 2 | I37: 2 | J37: Adriano ZIZU | K37: 2026 | L37: =VLOOKUP(J37,SERIES!B:K,10,FALSE) -> C | M37: =VLOOKUP(J37,SERIES!B:K,2,FALSE) -> 45 | N37: =VLOOKUP(J37,SERIES!B:K,9,FALSE) -> M | O37: C | P37: B | Q37: 2025 | T37: =H37 -> 2 | U37: 2 | V37: 2026 | W37: true
... A44: Almi Jr. FC | B44: Almi Jr. | C44: 2 | E44: ALMI | F44: 8 | H44: 8 | I44: 8 | J44: Almi Jr. FC | K44: 2026 | L44: =VLOOKUP(J44,SERIES!B:K,10,FALSE) -> B | M44: =VLOOKUP(J44,SERIES!B:K,2,FALSE) -> 39 | N44: =VLOOKUP(J44,SERIES!B:K,9,FALSE) -> R | O44: C | P44: C | Q44: 2025 | T44: =H44 -> 8 | U44: 3 | V44: 2026 | W44: true
A45: Borussia do Jaguaré | B45: Rogério Lagos | C45: 2 | E45: LAGOS | F45: 59 | H45: 59 | I45: 59 | J45: Borussia do Jaguaré | K45: 2026 | L45: C | M45: 51 | N45: M | O45: C | P45: C | Q45: 2025 | T45: =H45 -> 59 | U45: 3 | V45: 2026 | W45: true
A46: Xuchélides | B46: Chélide Teixeira | C46: 2 | E46: C TEIXEIRA | F46: 16 | H46: 16 | I46: 16 | J46: Xuchélides | K46: 2026 | L46: =VLOOKUP(J46,SERIES!B:K,10,FALSE) -> C | M46: =VLOOKUP(J46,SERIES!B:K,2,FALSE) -> 52 | N46: =VLOOKUP(J46,SERIES!B:K,9,FALSE) -> M | O46: C | P46: C | Q46: 2025 | T46: =H46 -> 16 | U46: 3 | V46: 2026 | W46: true
...

Sheet SERIES
J1: ST | P1: NOME_TIME | Q1: DIV 2025 | R1: POSICAO EM 2025 | S1: DIV 2026 D | T1: MOTIVO | U1: status[
A2: A | B2: Maletinhas F.C. | C2: 1 | D2: RICARDO MALETA | E2: 81 | F2: 29 | G2: 0 | H2: 9 | I2: 3262.38 | J2: C | K2: A | L2: =VLOOKUP(B2,ORG!J:K,2,FALSE) -> 2026 | P2: Maletinhas F.C. | Q2: A | R2: 1 | S2: A | T2: FICOU NA SERIE | U2: 2025
A3: A | B3: Sobottka FC 633 | C3: 2 | D3: GUSTAVO NERY | E3: 65 | F3: 23 | G3: 0 | H3: 15 | I3: 3291.58 | J3: M | K3: A | L3: =VLOOKUP(B3,ORG!J:K,2,FALSE) -> 2026 | P3: Sobottka FC 633 | Q3: A | R3: 2 | S3: A | T3: FICOU NA SERIE | U3: 2025
A4: A | B4: GIGANTES MORUMBI F.C | C4: 3 | D4: SERGIO GARCIA | E4: 62 | F4: 23 | G4: 0 | H4: 15 | I4: 3235.59 | J4: M | K4: A | L4: =VLOOKUP(B4,ORG!J:K,2,FALSE) -> 2026 | P4: GIGANTES MORUMBI F.C | Q4: A | R4: 3 | S4: A | T4: FICOU NA SERIE | U4: 2025
A5: A | B5: Adshow17 F.C | C5: 4 | D5: ADSON MENDES | E5: 60 | F5: 21 | G5: 0 | H5: 17 | I5: 3222.62 | J5: M | K5: A | L5: =VLOOKUP(B5,ORG!J:K,2,FALSE) -> 2026 | P5: Adshow17 F.C | Q5: A | R5: 4 | S5: A | T5: FICOU NA SERIE | U5: 2025
A6: A | B6: Schuletroll | C6: 5 | D6: SCHULAI 1 | E6: 60 | F6: 21 | G6: 0 | H6: 17 | I6: 3052.98 | J6: M | K6: A | L6: =VLOOKUP(B6,ORG!J:K,2,FALSE) -> 2026 | P6: Schuletroll | Q6: A | R6: 5 | S6: A | T6: FICOU NA SERIE | U6: 2025
A7: A | B7: LissaoCruzmaltino FC | C7: 6 | D7: LISSAO | E7: 59 | F7: 21 | G7: 0 | H7: 17 | I7: 3181.07 | J7: M | K7: A | L7: 2026 | P7: CamisaNegra FC | Q7: A | R7: 6 | S7: A | T7: FICOU NA SERIE | U7: 2025
A8: A | B8: Mitinga`s F.C | C8: 7 | D8: MARCEL CANTALEGO | E8: 58 | F8: 20 | G8: 0 | H8: 18 | I8: 3291.53 | J8: M | K8: A | L8: =VLOOKUP(B8,ORG!J:K,2,FALSE) -> 2026 | P8: Mitinga`s F.C | Q8: A | R8: 7 | S8: A | T8: FICOU NA SERIE | U8: 2025
A9: A | B9: FOI O QUE SOBROU | C9: 8 | D9: EDIPO MACEDO | E9: 55 | F9: 20 | G9: 0 | H9: 18 | I9: 3278.83 | J9: M | K9: A | L9: =VLOOKUP(B9,ORG!J:K,2,FALSE) -> 2026 | P9: FOI O QUE SOBROU | Q9: A | R9: 8 | S9: A | T9: FICOU NA SERIE | U9: 2025
A10: A | B10: Vuduzera | C10: 9 | D10: VUDU | E10: 54 | F10: 19 | G10: 0 | H10: 19 | I10: 3197.48 | J10: M | K10: A | L10: =VLOOKUP(B10,ORG!J:K,2,FALSE) -> 2026 | P10: Vuduzera | Q10: A | R10: 9 | S10: A | T10: FICOU NA SERIE | U10: 2025
A11: A | B11: ZEKABOLEIRO | C11: 10 | D11: RICARDO TRIPAO | E11: 54 | F11: 19 | G11: 0 | H11: 19 | I11: 3120.55 | J11: M | K11: A | L11: =VLOOKUP(B11,ORG!J:K,2,FALSE) -> 2026 | P11: ZEKABOLEIRO | Q11: A | R11: 10 | S11: A | T11: FICOU NA SERIE | U11: 2025
A12: A | B12: #Santos.Z/O | C12: 11 | D12: ALLAN SANTOS | E12: 53 | F12: 20 | G12: 0 | H12: 18 | I12: 3141.74 | J12: M | K12: A | L12: =VLOOKUP(B12,ORG!J:K,2,FALSE) -> #N/A | P12: EmesuShow Porcolino | Q12: A | R12: 12 | S12: A | T12: FICOU NA SERIE | U12: 2025
A13: A | B13: EmesuShow Porcolino | C13: 12 | D13: EMERSON PORCOLINO | E13: 52 | F13: 19 | G13: 0 | H13: 19 | I13: 3106.05 | J13: M | K13: A | L13: =VLOOKUP(B13,ORG!J:K,2,FALSE) -> 2026 | P13: TIMAO R.F.G | Q13: A | R13: 13 | S13: A | T13: FICOU NA SERIE | U13: 2025
A14: A | B14: RCUNHA S.C.C.P | C14: 13 | D14: ROBSON CUNHA | E14: 49 | F14: 17 | G14: 0 | H14: 21 | I14: 3115.84 | J14: M | K14: A | L14: 2026 | P14: PALM£IRAS S.E.P. | Q14: A | R14: 14 | S14: A | T14: FICOU NA SERIE | U14: 2025
A15: A | B15: Paleztra's Club | C15: 14 | D15: DIEGO PALMEIRESEN | E15: 48 | F15: 18 | G15: 0 | H15: 20 | I15: 3167.06 | J15: M | K15: A | L15: 2026 | P15: ZAGO PRATIS FC | Q15: A | R15: 16 | S15: A | T15: FICOU NA SERIE | U15: 2025
A16: A | B16: A.C. Fontana | C16: 15 | D16: ANDRE FONTANA | E16: 48 | F16: 18 | G16: 0 | H16: 20 | I16: 3121.49 | J16: M | K16: A | L16: =VLOOKUP(B16,ORG!J:K,2,FALSE) -> #N/A | P16: Luket Wanderes fc | Q16: B | R16: 21 | S16: A | T16: VAGA DIRETA | U16: 2025
A17: A | B17: REAL SARANDI CLUBE | C17: 16 | D17: ANDRE PRATS | E17: 46 | F17: 17 | G17: 0 | H17: 21 | I17: 2924.75 | J17: M | K17: A | L17: 2026 | P17: Amigos do Loco Abreu | Q17: B | R17: 22 | S17: A | T17: VAGA DIRETA | U17: 2025
A18: A | B18: Ipanema13 | C18: 17 | D18: ALEXANDRE IPANEMA | E18: 42 | F18: 16 | G18: 0 | H18: 22 | I18: 3190.84 | J18: R | K18: A | L18: =VLOOKUP(B18,ORG!J:K,2,FALSE) -> 2026 | P18: Metamoney F.C | Q18: B | R18: 23 | S18: A | T18: VAGA DIRETA | U18: 2025
A19: A | B19: OtoPat@ma | C19: 18 | D19: PAULO OTO | E19: 42 | F19: 15 | G19: 0 | H19: 23 | I19: 2970.04 | J19: R | K19: A | L19: =VLOOKUP(B19,ORG!J:K,2,FALSE) -> 2026 | P19: Silasbrs FC | Q19: B | R19: 24 | S19: A | T19: VAGA DIRETA | U19: 2025
A20: A | B20: Brabo Globetrotters | C20: 19 | D20: EDUARDO BRABO | E20: 41 | F20: 15 | G20: 0 | H20: 23 | I20: 2969.69 | J20: R | K20: A | L20: =VLOOKUP(B20,ORG!J:K,2,FALSE) -> 2026 | P20: Os Porko é Loko - Z/O | Q20: B | R20: 25 | S20: A | T20: VAGA POR DESISTENCIA | U20: 2025
A21: A | B21: Abóbora Futebol C | C21: 20 | D21: WELLIGTON ABOBORA | E21: 25 | F21: 9 | G21: 0 | H21: 29 | I21: 2472.85 | J21: R | K21: A | L21: =VLOOKUP(B21,ORG!J:K,2,FALSE) -> 2026 | P21: CRPELUSO | Q21: B | R21: 26 | S21: A | T21: VAGA POR DESISTENCIA | U21: 2025
P22: Ipanema13 | Q22: A | R22: 17 | S22: B | T22: REBAIXADO | U22: 2025
A23: B | B23: Luket Wanderes fc | C23: 21 | D23: LUCAT | E23: 78 | F23: 26 | G23: 1 | H23: 11 | I23: 3253.38 | J23: P | K23: B | L23: =VLOOKUP(B23,ORG!J:K,2,FALSE) -> 2026 | P23: OtoPat@ma | Q23: A | R23: 18 | S23: B | T23: REBAIXADO | U23: 2025
A24: B | B24: Amigos do Loco Abreu | C24: 22 | D24: RICARDO FILGUEIRAS | E24: 71 | F24: 26 | G24: 0 | H24: 12 | I24: 3224.90 | J24: P | K24: B | L24: =VLOOKUP(B24,ORG!J:K,2,FALSE) -> 2026 | P24: Brabo Globetrotters | Q24: A | R24: 19 | S24: B | T24: REBAIXADO | U24: 2025
A25: B | B25: Metamoney F.C | C25: 23 | D25: MARCIO GAI | E25: 69 | F25: 24 | G25: 1 | H25: 13 | I25: 3197.31 | J25: P | K25: B | L25: =VLOOKUP(B25,ORG!J:K,2,FALSE) -> 2026 | P25: Abóbora Futebol C | Q25: A | R25: 20 | S25: B | T25: REBAIXADO | U25: 2025
A26: B | B26: Silasbrs FC | C26: 24 | D26: SILINHAS | E26: 66 | F26: 23 | G26: 0 | H26: 15 | I26: 3221.26 | J26: P | K26: B | L26: =VLOOKUP(B26,ORG!J:K,2,FALSE) -> 2026 | P26: Sempre ForteF.C. | Q26: B | R26: 27 | S26: B | T26: FICOU NA SERIE | U26: 2025
A27: B | B27: Os Porko é Loko - Z/O | C27: 25 | D27: ANDERSON PORKO | E27: 63 | F27: 22 | G27: 0 | H27: 16 | I27: 3142.21 | J27: M | K27: B | L27: =VLOOKUP(B27,ORG!J:K,2,FALSE) -> 2026 | P27: Ferrugem Ultimate | Q27: B | R27: 28 | S27: B | T27: FICOU NA SERIE | U27: 2025
A28: B | B28: CRPELUSO | C28: 26 | D28: CLAUDIO PELUSO | E28: 60 | F28: 20 | G28: 0 | H28: 18 | I28: 3247.64 | J28: M | K28: B | L28: =VLOOKUP(B28,ORG!J:K,2,FALSE) -> 2026 | P28: 08 Ratto FC | Q28: B | R28: 29 | S28: B | T28: FICOU NA SERIE | U28: 2025
A29: B | B29: Sempre ForteF.C. | C29: 27 | D29: JONATHAN BATATA | E29: 60 | F29: 22 | G29: 0 | H29: 16 | I29: 3156.98 | J29: M | K29: B | L29: =VLOOKUP(B29,ORG!J:K,2,FALSE) -> 2026 | P29: GEJA | Q29: B | R29: 30 | S29: B | T29: FICOU NA SERIE | U29: 2025
A30: B | B30: Ferrugem Ultimate | C30: 28 | D30: THIAGO RIBAS | E30: 57 | F30: 20 | G30: 0 | H30: 18 | I30: 2895.37 | J30: M | K30: B | L30: =VLOOKUP(B30,ORG!J:K,2,FALSE) -> 2026 | P30: FUCKER AND SUCKER FC | Q30: B | R30: 32 | S30: B | T30: FICOU NA SERIE | U30: 2025
A31: B | B31: 08 Ratto FC | C31: 29 | D31: GABRIEL RATTO 1 | E31: 56 | F31: 20 | G31: 0 | H31: 18 | I31: 3250.32 | J31: M | K31: B | L31: =VLOOKUP(B31,ORG!J:K,2,FALSE) -> 2026 | P31: SC Ornaghi Paulista | Q31: B | R31: 33 | S31: B | T31: FICOU NA SERIE | U31: 2025
A32: B | B32: GEJA | C32: 30 | D32: WEDSON | E32: 54 | F32: 19 | G32: 0 | H32: 19 | I32: 3040.39 | J32: M | K32: B | L32: =VLOOKUP(B32,ORG!J:K,2,FALSE) -> 2026 | P32: Massiminismo FC | Q32: B | R32: 35 | S32: B | T32: FICOU NA SERIE | U32: 2025
A33: B | B33: SOROCITYSOCCER | C33: 31 | D33: ALEX TENIS MOURA | E33: 53 | F33: 19 | G33: 0 | H33: 19 | I33: 2959.86 | J33: M | K33: B | L33: =VLOOKUP(B33,ORG!J:K,2,FALSE) -> #N/A | P33: Bilao Sport Club | Q33: B | R33: 36 | S33: B | T33: FICOU NA SERIE | U33: 2025
A34: B | B34: FUCKER AND SUCKER FC | C34: 32 | D34: VERON | E34: 51 | F34: 18 | G34: 0 | H34: 20 | I34: 3105.52 | J34: M | K34: B | L34: =VLOOKUP(B34,ORG!J:K,2,FALSE) -> 2026 | P34: Botafogo Hell | Q34: C | R34: 41 | S34: B | T34: VAGA DIRETA | U34: 2025
... A41: B | B41: Almi Jr. FC | C41: 39 | D41: ALMI JUNIOR | E41: 32 | F41: 11 | G41: 0 | H41: 27 | I41: 2894.92 | J41: R | K41: B | L41: =VLOOKUP(B41,ORG!J:K,2,FALSE) -> 2026 | P41: Centenario Alviverde | Q41: C | R41: 50 | S41: B | T41: VAGA POR DESISTENCIA | U41: 2025
A42: B | B42: Caixão do Papaco | C42: 40 | D42: ADRIANO CUNHA EL LOUCO | E42: 31 | F42: 11 | G42: 0 | H42: 27 | I42: 2199.52 | J42: R | K42: B | P42: Gabirobense | Q42: B | R42: 37 | S42: C | T42: REBAIXADO | U42: 2025
P43: APELÕES FUTEBOL CLUB | Q43: B | R43: 38 | S43: C | T43: REBAIXADO | U43: 2025
A44: C | B44: Botafogo Hell | C44: 41 | D44: GABRIEL VUDU | E44: 77 | F44: 27 | G44: 1 | H44: 10 | I44: 3296.15 | J44: P | K44: C | L44: =VLOOKUP(B44,ORG!J:K,2,FALSE) -> 2026 | P44: Almi Jr. FC | Q44: B | R44: 39 | S44: C | T44: REBAIXADO | U44: 2025
A45: C | B45: Bike Cristo | C45: 42 | D45: MAURÍCIO VÉIO DA LARANJA | E45: 76 | F45: 27 | G45: 0 | H45: 11 | I45: 3268.83 | J45: P | K45: C | L45: =VLOOKUP(B45,ORG!J:K,2,FALSE) -> 2026 | P45: Borussia do Jaguaré | Q45: C | R45: 51 | S45: C | T45: FICOU NA SERIE | U45: 2025
A46: C | B46: J.V.Finhani | C46: 43 | D46: JEFFERSON FINHANI TI | E46: 75 | F46: 26 | G46: 0 | H46: 12 | I46: 3191.28 | J46: P | K46: C | L46: =VLOOKUP(B46,ORG!J:K,2,FALSE) -> 2026 | P46: Xuchélides | Q46: C | R46: 52 | S46: C | T46: FICOU NA SERIE | U46: 2025
...

Sheet GERAL 2025
A1: Ordem | B1: Jogador | C1: Time | D1: Pontos
A2: 74 | B2: ADRIANO CUNHA EL LOUCO | C2: Caixão do Papaco | D2: 2199.52
A3: 37 | B3: ADRIANO ZIZU | C3: Adriano ZIZU | D3: 3109.94
A4: 20 | B4: ADSON MENDES | C4: Adshow17 F.C | D4: 3222.62
A5: 56 | B5: ALEX TENIS MOURA | C5: SOROCITYSOCCER | D5: 2959.86
A6: 25 | B6: ALEXANDRE IPANEMA | C6: Ipanema13 | D6: 3190.84
A7: 44 | B7: ALLAN JAMES | C7: Centenario Alviverde | D7: 3080.53
A8: 33 | B8: ALLAN SANTOS | C8: #Santos.Z/O | D8: 3141.74
A9: 78 | B9: ALLEN | C9: Zona Leste Paulista | D9: 1689.29
A10: 62 | B10: ALMI JUNIOR | C10: Almi Jr. FC | D10: 2894.92
A11: 67 | B11: ALMIR RIMLAFC | C11: RIMLAFC | D11: 2752.76
A12: 16 | B12: ALYSON CALAZANS | C12: CalazansTeam | D12: 3244.03
A13: 32 | B13: ANDERSON PORKO | C13: Os Porko é Loko - Z/O | D13: 3142.21
... A62: 9 | B62: MAURÍCIO VÉIO DA LARANJA | C62: Bike Cristo | D62: 3268.83
A63: 63 | B63: MICHAEL REIS | C63: Kings Futebol Club | D63: 2893
A64: 70 | B64: OTAVIO DAMASCENO | C64: Timao do Otao | D64: 2536.86
A65: 53 | B65: PAULO OTO | C65: OtoPat@ma | D65: 2970.04
A66: 19 | B66: RICARDO FILGUEIRAS | C66: Amigos do Loco Abreu | D66: 3224.9
A67: 11 | B67: RICARDO MALETA | C67: Maletinhas F.C. | D67: 3262.38
A68: 57 | B68: RICARDO SHOJI | C68: Na Midola FC | D68: 2958.88
A69: 35 | B69: RICARDO TRIPAO | C69: ZEKABOLEIRO | D69: 3120.55
A70: 81 | B70: RICHARD MENEGUETI | C70: RMENEGHETTI | D70: 1487.35
A71: 36 | B71: ROBSON CUNHA | C71: RCUNHA S.C.C.P | D71: 3115.84
A72: 49 | B72: ROGÉRIO LAGOS | C72: Borussia da Pompeia | D72: 3051.13
A73: 48 | B73: SCHULAI 1 | C73: Schuletroll | D73: 3052.98
A74: 18 | B74: SERGIO GARCIA | C74: GIGANTES MORUMBI F.C | D74: 3235.59
A75: 21 | B75: SILINHAS | C75: Silasbrs FC | D75: 3221.26
... A80: 71 | B80: WELLIGTON ABOBORA | C80: Abóbora Futebol C | D80: 2472.85
A81: 66 | B81: WESLEY YORKS | C81: Yorks Gamora & Goku FC | D81: 2784
A82: 43 | B82: YURI ALLEJO | C82: Allejo Team F.C | D82: 3094.12

Sheet DUPLAS
A2: Silasbrs FC | E2: HPano FC | I2: Mariliense F.C
A3: Silas Siqueira | E3: Henrique Panobianco | I3: Nick
A4: 120.11 | E4: 98.38 | I4: 93.46
A5: 1º | E5: 1º | I5: 1º
A6: Não Escalou | E6: Não Escalou | I6: Não Escalou
A7: Acessar o perfil do time PALM£IRAS S.E.P. | E7: Acessar o perfil do time Botafogo Hell | I7: Acessar o perfil do time Botafogo Hell
A9: PALM£IRAS S.E.P. | E9: Botafogo Hell | I9: Botafogo Hell
A10: Diego Longo | E10: Gabriel | I10: Gabriel
A11: 114.41 | E11: 97.68 | I11: 90.26
A12: 2º | E12: 2º | I12: 2º
A13: Escalou | E13: Não Escalou | I13: Escalou
A14: Acessar o perfil do time Botafogo Hell | E14: Acessar o perfil do time Marco-FSA | I14: Acessar o perfil do time Na Midola FC
... A398: Não Escalou | E398: Não Escalou | I398: Não Escalou
A399: Acessar o perfil do time DIDIBRE FC
A401: DIDIBRE FC
A402: Diego Nogueira
A403: 24.25
A404: 58º
A405: Não Escalou

Sheet Col Val D
C1: b2 | F1: b2
B2: HPano FC | C2: 1 | E2: Mariliense F.C | F2: 1
B3: Henrique Panobianco | C3: 2 | E3: Nick | F3: 2
B4: 98.38 | C4: 3 | E4: 93.46 | F4: 3
B5: 1º | C5: 4 | E5: 1º | F5: 4
B6: Não Escalou | C6: 5 | E6: Não Escalou | F6: 5
B7: Acessar o perfil do time Botafogo Hell | C7: 6 | E7: Acessar o perfil do time Botafogo Hell | F7: 6
C8: 7 | F8: 7
B9: Botafogo Hell | C9: 1 | E9: Botafogo Hell | F9: 1
B10: Gabriel | C10: 2 | E10: Gabriel | F10: 2
B11: 97.68 | C11: 3 | E11: 90.26 | F11: 3
B12: 2º | C12: 4 | E12: 2º | F12: 4
B13: Não Escalou | C13: 5 | E13: Escalou | F13: 5
B14: Acessar o perfil do time Marco-FSA | C14: 6 | E14: Acessar o perfil do time Na Midola FC | F14: 6
C15: 7 | F15: 7
B16: Marco-FSA | C16: 1 | E16: Na Midola FC | F16: 1
B17: MarcoCzDutra | C17: 2 | E17: Shoji | F17: 2
B18: 97.48 | C18: 3 | E18: 89.56 | F18: 3
B19: 3º | C19: 4 | E19: 3º | F19: 4
B20: Não Escalou | C20: 5 | E20: Não Escalou | F20: 5
B21: Acessar o perfil do time Mariliense F.C | C21: 6 | E21: Acessar o perfil do time Real Rattaria FC | F21: 6
C22: 7 | F22: 7
B23: Mariliense F.C | C23: 1 | E23: Real Rattaria FC | F23: 1
B24: Nick | C24: 2 | E24: Gabriel Ratto | F24: 2
B25: 91.70 | C25: 3 | E25: 84.86 | F25: 3
B26: 4º | C26: 4 | E26: 4º | F26: 4
B27: Não Escalou | C27: 5 | E27: Não Escalou | F27: 5
B28: Acessar o perfil do time Real Rattaria FC | C28: 6 | E28: Acessar o perfil do time Machadotti1972 | F28: 6
C29: 7 | F29: 7
B30: Real Rattaria FC | C30: 1 | E30: Machadotti1972 | F30: 1
B31: Gabriel Ratto | C31: 2 | E31: Gabriel Machado | F31: 2
B32: 89.99 | C32: 3 | E32: 83.16 | F32: 3
B33: 5º | C33: 4 | E33: 5º | F33: 4
B34: Não Escalou | C34: 5 | E34: Não Escalou | F34: 5
B35: Acessar o perfil do time Machadotti1972 | C35: 6 | E35: Acessar o perfil do time CalazansTeam | F35: 6
C36: 7 | F36: 7
B37: Machadotti1972 | C37: 1 | E37: CalazansTeam | F37: 1
B38: Gabriel Machado | C38: 2 | E38: ALYSON | F38: 2
B39: 89.79 | C39: 3 | E39: 82.76 | F39: 3
B40: 6º | C40: 4 | E40: 6º | F40: 4
...

Sheet Colagem D
A1: Parrudo'S Team | B1: 133.58 | D1: Silasbrs FC | E1: 120.11 | G1: HPano FC | H1: 98.38 | J1: Mariliense F.C | K1: 93.46
A2: DEIZÃO FUTEBOL CLUBE | B2: 130.68 | D2: PALM£IRAS S.E.P. | E2: 114.41 | G2: Botafogo Hell | H2: 97.68 | J2: Botafogo Hell | K2: 90.26
A3: TIMAO R.F.G | B3: 130.68 | D3: Botafogo Hell | E3: 114.21 | G3: Marco-FSA | H3: 97.48 | J3: Na Midola FC | K3: 89.56
A4: FOI O QUE SOBROU | B4: 127.18 | D4: Allejo Team F.C | E4: 113.81 | G4: Mariliense F.C | H4: 91.70 | J4: Real Rattaria FC | K4: 84.86
A5: GIGANTES MORUMBI F.C | B5: 124.08 | D5: Mala03Fc | E5: 113.71 | G5: Real Rattaria FC | H5: 89.99 | J5: Machadotti1972 | K5: 83.16
A6: PALM£IRAS S.E.P. | B6: 123.98 | D6: GIGANTES MORUMBI F.C | E6: 113.43 | G6: Machadotti1972 | H6: 89.79 | J6: CalazansTeam | K6: 82.76
A7: Mitinga`s F.C | B7: 122.58 | D7: Olimpingas Sport Club | E7: 112.21 | G7: Tua Mãe SEP | H7: 89.58 | J7: Olimpingas Sport Club | K7: 81.86
A8: Ipanema13 | B8: 122.58 | D8: HPano FC | E8: 111.91 | G8: Wedgol | H8: 88.80 | J8: Mosby | K8: 81.56
A9: Burza F C | B9: 121.08 | D9: Parrudo'S Team | E9: 110.81 | G9: Burza F C | H9: 88.50 | J9: 08 Ratto FC | K9: 80.66
A10: Pelicano Papada F.C | B10: 119.08 | D10: 08 Ratto FC | E10: 109.61 | G10: Silasbrs FC | H10: 88.16 | J10: J.V.Finhani | K10: 79.95
A11: Wedgol | B11: 118.88 | D11: SÓRRESTO | E11: 109.01 | G11: SÓRRESTO | H11: 88.10 | J11: Joga Tranquilo F.S. | K11: 79.06
A12: Mariliense F.C | B12: 118.68 | D12: Sobottka FC 633 | E12: 108.85 | G12: Andico F.C | H12: 87.56 | J12: Ipanema13 | K12: 79.06
... A57: Xuchélides | B57: 44.85 | D57: nascimento124 | E57: 38.45 | G57: nascimento124 | H57: 16.90 | J57: DIDIBRE FC | K57: 24.34
A58: DIDIBRE FC | B58: 38.70 | D58: DIDIBRE FC | E58: 24.25

Sheet base_2026_D
A1: Dupla | B1: Nome Cartoleiro 1 | C1: Time Cartoleiro 1 | D1: Dupla | F1: time | G1: Nome | I1: Nome | M1: id | N1: ano | P1: POS | Q1: TIME 1 | R1: id1 | S1: TIME 2 | T1: id2 | U1: PT1 | V1: PT2 | W1: TOTA ROD1
A2: 1 | B2: Elza Gadelha Quirino | C2: Miss Procon Futebol Clube | D2: Daniel Quirino | F2: CalazansTeam | G2: A CALAZANS | H2: =VLOOKUP(G2,J:K,2,FALSE) -> 1 | I2: CalazansTeam | J2: A CALAZANS | K2: 1 | M2: 1 | N2: 2026 | P2: 1º | Q2: Didibre FC | R2: 14 | S2: nascimento124 | T2: 40 | U2: 90.05 | V2: 70.26 | W2: =SUM(U2:V2) -> 160.31
A3: 1 | B3: Daniel Quirino | C3: Olimpingas Sport Club | D3: Elza Gadelha Quirino | F3: Mariliense F.C | G3: A CARLOS | H3: =VLOOKUP(G3,J:K,2,FALSE) -> 2 | I3: Mariliense F.C | J3: A CARLOS | K3: 2 | M3: 2 | N3: 2026 | P3: 2º | Q3: Na Midola FC | R3: 39 | S3: Mosby | T3: 38 | U3: 94.26 | V3: 60.26 | W3: =SUM(U3:V3) -> 154.52
A4: 2 | B4: Wedson | C4: GEJA | D4: Wedgol | F4: Adshow17 F.C | G4: ADSON | H4: =VLOOKUP(G4,J:K,2,FALSE) -> 3 | I4: Adshow17 F.C | J4: ADSON | K4: 3 | M4: 3 | N4: 2026 | P4: 3º | Q4: Machadotti1972 | R4: 30 | S4: Realmengo07 Fc | T4: 46 | U4: 74.96 | V4: 74.96 | W4: =SUM(U4:V4) -> 149.92
A5: 2 | B5: Wedson | C5: Wedgol | D5: GEJA | F5: Ipanema13 | G5: ALE CHINELO | H5: =VLOOKUP(G5,J:K,2,FALSE) -> 4 | I5: Ipanema13 | J5: ALE CHINELO | K5: 4 | M5: 4 | N5: 2026 | P5: 4º | Q5: Massiminismo FC | R5: 35 | S5: Real Rattaria FC | T5: 45 | U5: 68.96 | V5: 78.46 | W5: =SUM(U5:V5) -> 147.42
A6: 3 | B6: Adson Mendes | C6: Adshow 17 | D6: Sobottka FC 633 | F6: Almi Jr. FC | G6: ALMI | H6: =VLOOKUP(G6,J:K,2,FALSE) -> 5 | I6: Almi Jr. FC | J6: ALMI | K6: 5 | M6: 5 | N6: 2026 | P6: 5º | Q6: GEJA | R6: 21 | S6: Wedgol | T6: 57 | U6: 69.1 | V6: 74.7 | W6: =SUM(U6:V6) -> 143.8
A7: 3 | B7: Gustavo Nery | C7: Sobottka FC 633 | D7: Adshow 17 | F7: Andico F.C | G7: ANDICO | H7: =VLOOKUP(G7,J:K,2,FALSE) -> 6 | I7: Andico F.C | J7: ANDICO | K7: 6 | M7: 6 | N7: 2026 | P7: 6º | Q7: Botafogo Hell | R7: 9 | S7: Hpano FC | T7: 24 | U7: 63.5 | V7: 78.7 | W7: =SUM(U7:V7) -> 142.2
A8: 4 | B8: Maurício Véio da Laranja | C8: Bike Cristo | D8: Real Sarandi Clube | F8: mala03fc | G8: B DUCATI | H8: =VLOOKUP(G8,J:K,2,FALSE) -> 7 | I8: mala03fc | J8: B DUCATI | K8: 7 | M8: 7 | N8: 2026 | P8: 7º | Q8: CalazansTeam | R8: 12 | S8: J.V.Finhani | T8: 26 | U8: 66.86 | V8: 68.4 | W8: =SUM(U8:V8) -> 135.26
A9: 4 | B9: André Prates 1 | C9: Zago Pratis | D9: Bike Cristo | F9: Brabo Globetrotters | G9: BRABO | H9: =VLOOKUP(G9,J:K,2,FALSE) -> 8 | I9: Brabo Globetrotters | J9: BRABO | K9: 8 | M9: 8 | N9: 2026 | P9: 8º | Q9: Andico F.C | R9: 7 | S9: Burza F C | T9: 11 | U9: 65.4 | V9: 69.5 | W9: =SUM(U9:V9) -> 134.9
A10: 5 | B10: Lucas Massimini | C10: Massiminismo FC | D10: Real Rattaria FC | F10: Burza F C | G10: BURZA | H10: =VLOOKUP(G10,J:K,2,FALSE) -> 9 | I10: Burza F C | J10: BURZA | K10: 9 | M10: 9 | N10: 2026 | P10: 9º | Q10: Joga Tranquilo F.S. | R10: 27 | S10: SAY ZIKA | T10: 48 | U10: 74.2 | V10: 57.36 | W10: =SUM(U10:V10) -> 131.56
A11: 5 | B11: Gabriel Ratto 2 | C11: Real Rattaria FC | D11: Massiminismo FC | F11: Xuchélides | G11: C TEIXEIRA | H11: =VLOOKUP(G11,J:K,2,FALSE) -> 10 | I11: Xuchélides | J11: C TEIXEIRA | K11: 10 | M11: 10 | N11: 2026 | P11: 10º | Q11: Brabo Globetrotters | R11: 10 | S11: A D Peaky Blinders | T11: 2 | U11: 56.46 | V11: 73.8 | W11: =SUM(U11:V11) -> 130.26
A12: 6 | B12: Alyson Calazans | C12: CalazansTeam | D12: J.V.Finhani | F12: Grajaux City F.C. | G12: D FERREIRA | H12: =VLOOKUP(G12,J:K,2,FALSE) -> 11 | I12: Grajaux City F.C. | J12: D FERREIRA | K12: 11 | M12: 11 | N12: 2026 | P12: 11º | Q12: Adshow17 F.C | R12: 3 | S12: Sobottka FC 633 | T12: 52 | U12: 62.16 | V12: 66.8 | W12: =SUM(U12:V12) -> 128.96
A13: 6 | B13: Jefferson Finhani TI | C13: J.V.Finhani | D13: CalazansTeam | F13: Tupinianos FC | G13: D FERREIRA | H13: =VLOOKUP(G13,J:K,2,FALSE) -> 11 | I13: Tupinianos FC | J13: D LONGO | K13: 12 | M13: 12 | N13: 2026 | P13: 12º | Q13: Ipanema13 | R13: 25 | S13: Mariliense F.C | T13: 34 | U13: 64.46 | V13: 64.46 | W13: =SUM(U13:V13) -> 128.92
... A33: 16 | B33: Lucat | C33: Luket Wanderes fc | D33: E.C. Ocram 5.5 | F33: J.V.Finhani | G33: J FINHANI | H33: =VLOOKUP(G33,J:K,2,FALSE) -> 30 | I33: J.V.Finhani | J33: L MASSIMINI | K33: 32 | M33: 32 | N33: 2026 | P33: 32º | Q33: Gigantes Morumbi F.C | R33: 22 | S33: TIMAO R.F.G | T33: 54 | U33: 39.26 | V33: 50.56 | W33: =SUM(U33:V33) -> 89.82
A34: 17 | B34: Lucat | C34: Al Ahly Ecc | D34: Pelicano Papada | F34: A D Peaky Blinders | G34: KAJURU | H34: =VLOOKUP(G34,J:K,2,FALSE) -> 31 | I34: A D Peaky Blinders | J34: LUCAT | K34: 33 | M34: 33 | N34: 2026
A35: 17 | B35: Leandro Schulai 3 | C35: Pelicano Papada | D35: Luket Wanderes fc | F35: Massiminismo FC | G35: L MASSIMINI | H35: =VLOOKUP(G35,J:K,2,FALSE) -> 32 | I35: Massiminismo FC | J35: LUKET | K35: 34 | M35: 34 | N35: 2026
A36: 18 | B36: Thiago Ribas | C36: Ferrugem Ultimate | D36: Marco-FSA | F36: Al Ahly Ecc | G36: LUCAT | H36: =VLOOKUP(G36,J:K,2,FALSE) -> 33 | I36: Al Ahly Ecc | J36: LUTTY | K36: 35 | M36: 35 | N36: 2026
A37: 18 | B37: Marco Amigo Thiago Ribas | C37: Marco-FSA | D37: Thiago Ribas | F37: Luket Wanderes fc | G37: LUKET | H37: =VLOOKUP(G37,J:K,2,FALSE) -> 34 | I37: Luket Wanderes fc | J37: M CANTALEGO | K37: 36 | M37: 36 | N37: 2026
A38: 19 | B38: Eduardo Ornaghi | C38: SC Ornaghi Paulista | D38: Real Sarandi Clube | F38: Sanlutty FC | G38: LUTTY | H38: =VLOOKUP(G38,J:K,2,FALSE) -> 35 | I38: Sanlutty FC | J38: M COIMBRA | K38: 37 | M38: 37 | N38: 2026
A39: 19 | B39: André Prates 2 | C39: Zago Pratis | D39: SC Ornaghi Paulista | F39: Mitinga`s F.C | G39: M CANTALEGO | H39: =VLOOKUP(G39,J:K,2,FALSE) -> 36 | I39: Mitinga`s F.C | J39: M OCRAM | K39: 38 | M39: 38 | N39: 2026
A40: 20 | B40: Marcel Cantalego | C40: Mitinga's F.C | D40: Silasbrs FC | F40: Realmengo07 Fc | G40: M COIMBRA | H40: =VLOOKUP(G40,J:K,2,FALSE) -> 37 | I40: Realmengo07 Fc | J40: ORNAGHI | K40: 39 | M40: 39 | N40: 2026
A41: 20 | B41: Silas | C41: Silasbrs FC | D41: Mitinga's F.C | F41: E.C. Ocram 5.6 | G41: M OCRAM | H41: =VLOOKUP(G41,J:K,2,FALSE) -> 38 | I41: E.C. Ocram 5.6 | J41: PRATIS | K41: 40 | M41: 40 | N41: 2026
A42: 21 | B42: Alexandre Carlos | C42: Ipanema 13 | D42: Mariliense | F42: SC Ornaghi Paulista | G42: ORNAGHI | H42: =VLOOKUP(G42,J:K,2,FALSE) -> 39 | I42: SC Ornaghi Paulista | J42: R CUNHA | K42: 41 | M42: 41 | N42: 2026
A43: 21 | B43: Alexandre Carlos | C43: Mariliense | D43: Ipanema 13 | F43: ZAGO PRATIS FC | G43: PRATIS | H43: =VLOOKUP(G43,J:K,2,FALSE) -> 40 | I43: ZAGO PRATIS FC | J43: R MALETA | K43: 42 | M43: 42 | N43: 2026
A44: 22 | B44: Andico | C44: Andico F.C | D44: Burza | F44: TIMAO R.F.G | G44: R CUNHA | H44: =VLOOKUP(G44,J:K,2,FALSE) -> 41 | I44: TIMAO R.F.G | J44: R SHOJI | K44: 43 | M44: 43 | N44: 2026
A45: 22 | B45: Burza | C45: Burza FC | D45: Andico | F45: Maletinhas F.C. | G45: R MALETA | H45: =VLOOKUP(G45,J:K,2,FALSE) -> 42 | I45: Maletinhas F.C. | J45: R TRIPAO | K45: 44 | M45: 44 | N45: 2026
... A53: 26 | B53: Enzo Nascimento | C53: Nascimento 124 | D53: Diego Valadares | F53: Schuletroll | G53: SCHULETA | H53: =VLOOKUP(G53,J:K,2,FALSE) -> 47 | I53: Schuletroll | J53: Y ALLEJO | K53: 52 | M53: 52 | N53: 2026
A54: 27 | B54: Guilherme Felicio | C54: F.C Felicio F.C | D54: Giovanni Castro | F54: Ferrugem Ultimate | G54: T RIBAS | H54: =VLOOKUP(G54,J:K,2,FALSE) -> 48 | I54: Ferrugem Ultimate | M54: 53 | N54: 2026
A55: 27 | B55: Giovanni Castro | C55: Tua mãe SEP | D55: Guilherme Felicio | F55: Marco-FSA | G55: T RIBAS | H55: =VLOOKUP(G55,J:K,2,FALSE) -> 48 | I55: Marco-FSA | M55: 54 | N55: 2026
A56: 29 | B56: Yuri Oliveira | C56: Allejo Team F.C | D56: William Pereira | F56: Bike Cristo | G56: VEIO DA LARANJA | H56: =VLOOKUP(G56,J:K,2,FALSE) -> 49 | I56: Bike Cristo | M56: 55 | N56: 2026
A57: 29 | B57: William Pereira | C57: Juquitas FC | D57: Yuri Oliveira | F57: Juquitas FC | G57: W SILVA | H57: =VLOOKUP(G57,J:K,2,FALSE) -> 50 | I57: Juquitas FC | M57: 56 | N57: 2026
A58: 30 | B58: Ricardo Shoji | C58: Na Midola FC | D58: Mosby 1 | F58: GEJA | G58: WED | H58: =VLOOKUP(G58,J:K,2,FALSE) -> 51 | I58: GEJA | M58: 57 | N58: 2026
A59: 30 | B59: Felipe Mosby | C59: Mosby | D59: Shoju | F59: Wedgol | G59: WED | H59: =VLOOKUP(G59,J:K,2,FALSE) -> 51 | I59: Wedgol | M59: 58 | N59: 2026
A60: 31 | B60: Maletas | C60: Maletinhas F.C. | D60: Robson 2 | F60: Allejo Team F.C | G60: Y ALLEJO | H60: =VLOOKUP(G60,J:K,2,FALSE) -> 52 | I60: Allejo Team F.C | M60: 59 | N60: 2026
A61: 31 | B61: Robson 2 | C61: Deizão Futebol Clube | D61: Maletinhas
A62: 32 | B62: Eduardo Ornaghi 2 | C62: SC Ornaghi Paulista | D62: Maurício Véio da Laranja 2
A63: 32 | B63: Maurício Véio da Laranja 2 | C63: Bike Cristo | D63: Eduardo Ornaghi 2
A64: 33 | C64: Brabo Globetrotters
A65: 33 | C65: A D Peaky Blinders

Sheet Planilha6
A1: id | B1: cartoleiro_id | C1: nome | D1: id | F1: Didibre FC | G1: =VLOOKUP(F1,C:D,2,FALSE) -> 16 | I1: 1 | K1: nascimento124 | L1: =VLOOKUP(K1,C:D,2,FALSE) -> 20 | N1: 1 | O1: 20 | P1: 2026 | Q1: O Nascimento do Dibre | R1: 1 | T1: id | U1: ano | V1: nome
A2: 1 | B2: 1 | C2: CalazansTeam | D2: 1 | F2: Na Midola FC | G2: =VLOOKUP(F2,C:D,2,FALSE) -> 45 | I2: 2 | K2: Mosby | L2: =VLOOKUP(K2,C:D,2,FALSE) -> 22 | N2: 2 | O2: 22 | P2: 2026 | Q2: Mosby na Midola | R2: 2 | T2: 1 | U2: 2026 | V2: O Nascimento do Dibre
A3: 2 | B3: 2 | C3: Mariliense F.C | D3: 2 | F3: Machadotti1972 | G3: =VLOOKUP(F3,C:D,2,FALSE) -> 26 | I3: 3 | K3: Realmengo07 Fc | L3: =VLOOKUP(K3,C:D,2,FALSE) -> 39 | N3: 3 | O3: 39 | P3: 2026 | Q3: Machadada no Mengo | R3: 3 | T3: 2 | U3: 2026 | V3: Mosby na Midola
A4: 3 | B4: 3 | C4: Adshow17 F.C | D4: 3 | F4: Massiminismo FC | G4: =VLOOKUP(F4,C:D,2,FALSE) -> 34 | I4: 4 | K4: Real Rattaria FC | L4: =VLOOKUP(K4,C:D,2,FALSE) -> 28 | N4: 4 | O4: 28 | P4: 2026 | Q4: Rattaria Máxima | R4: 4 | T4: 3 | U4: 2026 | V4: Machadada no Mengo
A5: 4 | B5: 4 | C5: Ipanema13 | D5: 4 | F5: GEJA | G5: =VLOOKUP(F5,C:D,2,FALSE) -> 57 | I5: 5 | K5: Wedgol | L5: =VLOOKUP(K5,C:D,2,FALSE) -> 58 | N5: 5 | O5: 58 | P5: 2026 | Q5: Geja o Gol | R5: 5 | T5: 4 | U5: 2026 | V5: Rattaria MÃ¡xima
A6: 5 | B6: 5 | C6: Almi Jr. FC | D6: 5 | F6: Botafogo Hell | G6: =VLOOKUP(F6,C:D,2,FALSE) -> 23 | I6: 6 | K6: Hpano FC | L6: =VLOOKUP(K6,C:D,2,FALSE) -> 31 | N6: 6 | O6: 31 | P6: 2026 | Q6: Pano no Inferno | R6: 6 | T6: 5 | U6: 2026 | V6: Geja o Gol
A7: 6 | B7: 6 | C7: Andico F.C | D7: 6 | F7: CalazansTeam | G7: =VLOOKUP(F7,C:D,2,FALSE) -> 1 | I7: 7 | K7: J.V.Finhani | L7: =VLOOKUP(K7,C:D,2,FALSE) -> 32 | N7: 7 | O7: 32 | P7: 2026 | Q7: Cala e Finja | R7: 7 | T7: 6 | U7: 2026 | V7: Pano no Inferno
A8: 7 | B8: 7 | C8: mala03fc | D8: 7 | F8: Andico F.C | G8: =VLOOKUP(F8,C:D,2,FALSE) -> 6 | I8: 8 | K8: Burza F C | L8: =VLOOKUP(K8,C:D,2,FALSE) -> 9 | N8: 8 | O8: 9 | P8: 2026 | Q8: Burzandico | R8: 8 | T8: 7 | U8: 2026 | V8: Cala e Finja
A9: 8 | B9: 8 | C9: Brabo Globetrotters | D9: 8 | F9: Joga Tranquilo F.S. | G9: =VLOOKUP(F9,C:D,2,FALSE) -> 18 | I9: 9 | K9: SAY ZIKA | L9: =VLOOKUP(K9,C:D,2,FALSE) -> 46 | N9: 9 | O9: 46 | P9: 2026 | Q9: Tranquilidade Zicada | R9: 9 | T9: 8 | U9: 2026 | V9: Burzandico
A10: 9 | B10: 9 | C10: Burza F C | D10: 9 | F10: Brabo Globetrotters | G10: =VLOOKUP(F10,C:D,2,FALSE) -> 8 | I10: 10 | K10: A D Peaky Blinders | L10: =VLOOKUP(K10,C:D,2,FALSE) -> 33 | N10: 10 | O10: 33 | P10: 2026 | Q10: Globetrotters Frios e Calculistas | R10: 10 | T10: 9 | U10: 2026 | V10: Tranquilidade Zicada
A11: 10 | B11: 10 | C11: Xuchélides | D11: 10 | F11: Adshow17 F.C | G11: =VLOOKUP(F11,C:D,2,FALSE) -> 3 | I11: 11 | K11: Sobottka FC 633 | L11: =VLOOKUP(K11,C:D,2,FALSE) -> 29 | N11: 11 | O11: 29 | P11: 2026 | Q11: AdShottta | R11: 11 | T11: 10 | U11: 2026 | V11: Globetrotters Frios e Calculistas
A12: 11 | B12: 11 | C12: Grajaux City F.C. | D12: 11 | F12: Ipanema13 | G12: =VLOOKUP(F12,C:D,2,FALSE) -> 4 | I12: 12 | K12: Mariliense F.C | L12: =VLOOKUP(K12,C:D,2,FALSE) -> 2 | N12: 12 | O12: 2 | P12: 2026 | Q12: Garota de Marília | R12: 12 | T12: 11 | U12: 2026 | V12: AdShottta
A13: 12 | B13: 11 | C13: Tupinianos FC | D13: 12 | F13: Al Ahly Ecc | G13: =VLOOKUP(F13,C:D,2,FALSE) -> 35 | I13: 13 | K13: Pelicano Papada F.C | L13: =VLOOKUP(K13,C:D,2,FALSE) -> 51 | N13: 13 | O13: 51 | P13: 2026 | Q13: Pelicano do Egito | R13: 13 | T13: 12 | U13: 2026 | V13: Garota de MarÃ­lia
... A32: 31 | B32: 29 | C32: Hpano FC | D32: 31 | F32: Gigantes Morumbi F.C | G32: =VLOOKUP(F32,C:D,2,FALSE) -> 49 | I32: 32 | K32: TIMAO R.F.G | L32: =VLOOKUP(K32,C:D,2,FALSE) -> 43 | N32: 32 | O32: 43 | P32: 2026 | Q32: Debi e Loide | R32: 32 | T32: 31 | U32: 2026 | V32: Marco Enferrujado
A33: 32 | B33: 30 | C33: J.V.Finhani | D33: 32 | N33: 1 | O33: 16 | T33: 32 | U33: 2026 | V33: Debi e Loide
A34: 33 | B34: 31 | C34: A D Peaky Blinders | D34: 33 | N34: 2 | O34: 45
A35: 34 | B35: 32 | C35: Massiminismo FC | D35: 34 | N35: 3 | O35: 26
A36: 35 | B36: 33 | C36: Al Ahly Ecc | D36: 35 | N36: 4 | O36: 34
A37: 36 | B37: 34 | C37: Luket Wanderes fc | D37: 36 | N37: 5 | O37: 57
