Workbook

Sheet Planilha1
A6: Na Midola FC
A7: Shoji
A8: 46367
A9: -90.06
A10: -
A11: 0.00
A12: -1º
A18: AvantiPalestraFC
A19: Tiago Matias Dias
A20: 46367
A21: -82.25
A22: -
A23: 0.00
A24: -2º
A30: Real Rattaria FC
A31: Gabriel Ratto
A32: 46367
A33: -73.96
A34: -
A35: 0.00
A36: -3º
A42: Lanterninha Futebol Clube
A43: Robson Taglia
A44: 46366
A45: -73.45
A46: -
A47: 0.00
A48: -4º
A54: Borussia do Jaguaré
A55: Rogério Lagos
A56: 46368
A57: -72.35
A58: -
A59: 0.00
A60: -5º
A66: Luket Wanderes fc
A67: Lucas Silva Vieira
A68: 46367
A69: -68.36
A70: -
...

Sheet Planilha4
A1: A | B1: B
A2: Na Midola FC | B2: 1
A3: Shoji | B3: 2
A4: 46367 | B4: 3
A5: -90.06 | B5: 4
A6: - | B6: 5
A7: 0.00 | B7: 6
A8: -1º | B8: 7
B9: 8
B10: 9
B11: 10
B12: 11
B13: 12
A14: AvantiPalestraFC | B14: 1
A15: Tiago Matias Dias | B15: 2
A16: 46367 | B16: 3
A17: -82.25 | B17: 4
A18: - | B18: 5
A19: 0.00 | B19: 6
A20: -2º | B20: 7
B21: 8
B22: 9
B23: 10
B24: 11
B25: 12
A26: Real Rattaria FC | B26: 1
A27: Gabriel Ratto | B27: 2
A28: 46367 | B28: 3
A29: -73.96 | B29: 4
A30: - | B30: 5
A31: 0.00 | B31: 6
A32: -3º | B32: 7
B33: 8
B34: 9
B35: 10
B36: 11
B37: 12
A38: Lanterninha Futebol Clube | B38: 1
A39: Robson Taglia | B39: 2
A40: 46366 | B40: 3
...

Sheet Planilha8
A2: EmesuShow Porcolino | M2: Bilao Sport Club
A3: Emerson Rocha | M3: Gabriel Alencar
A4: 118.86 | M4: C$ 326.99
A5: 1º | M5: 1º
A6: Não Escalou | M6: Não Escalou
A7: Acessar o perfil do time Bike Cristo | M7: Acessar o perfil do time LMD FC
A9: Bike Cristo | M9: LMD FC
A10: Maurício Silva | M10: Lucas Matias
A11: 107.66 | M11: C$ 187.22
A12: 2º | M12: 2º
A13: Escalou | M13: Não Escalou
A14: Acessar o perfil do time Andico F.C | M14: Acessar o perfil do time AvantiPalestraFC
... A580: Não Escalou | M580: Não Escalou

Sheet Col Val
B1: c2 | E1: c2 | H1: c2 | K1: c2 | N1: c2 | Q1: c2
A2: FOI O QUE SOBROU | B2: 1 | D2: Bilao Sport Club | E2: 1 | G2: SE Coringas do Piero | H2: 1 | J2: Bilao Sport Club | K2: 1 | M2: EmesuShow Porcolino | N2: 1 | P2: Bilao Sport Club | Q2: 1
A3: V. ÉDIPO | B3: 2 | D3: Gabriel Alencar | E3: 2 | G3: Enrico Piero | H3: 2 | J3: Gabriel Alencar | K3: 2 | M3: Emerson Rocha | N3: 2 | P3: Gabriel Alencar | Q3: 2
A4: 119.98 | B4: 3 | D4: C$ 319.41 | E4: 3 | G4: 117.54 | H4: 3 | J4: C$ 325.83 | K4: 3 | M4: 118.86 | N4: 3 | P4: C$ 326.99 | Q4: 3
A5: 1º | B5: 4 | D5: 1º | E5: 4 | G5: 1º | H5: 4 | J5: 1º | K5: 4 | M5: 1º | N5: 4 | P5: 1º | Q5: 4
A6: Não Escalou | B6: 5 | D6: Não Escalou | E6: 5 | G6: Escalou | H6: 5 | J6: Não Escalou | K6: 5 | M6: Não Escalou | N6: 5 | P6: Não Escalou | Q6: 5
A7: Acessar o perfil do time Abóbora Futebol C | B7: 6 | D7: Acessar o perfil do time AvantiPalestraFC | E7: 6 | G7: Acessar o perfil do time Gabirobense | H7: 6 | J7: Acessar o perfil do time APELÕES FUTEBOL CLUB | K7: 6 | M7: Acessar o perfil do time Bike Cristo | N7: 6 | P7: Acessar o perfil do time LMD FC | Q7: 6
B8: 7 | E8: 7 | H8: 7 | K8: 7 | N8: 7 | Q8: 7
A9: Abóbora Futebol C | B9: 1 | D9: AvantiPalestraFC | E9: 1 | G9: Gabirobense | H9: 1 | J9: APELÕES FUTEBOL CLUB | K9: 1 | M9: Bike Cristo | N9: 1 | P9: LMD FC | Q9: 1
A10: Wellyngton Remesso | B10: 2 | D10: Tiago Matias Dias | E10: 2 | G10: Cadé | H10: 2 | J10: Greg Quirino | K10: 2 | M10: Maurício Silva | N10: 2 | P10: Lucas Matias | Q10: 2
A11: 114.96 | B11: 3 | D11: C$ 186.17 | E11: 3 | G11: 115.78 | H11: 3 | J11: C$ 185.79 | K11: 3 | M11: 107.66 | N11: 3 | P11: C$ 187.22 | Q11: 3
A12: 2º | B12: 4 | D12: 2º | E12: 4 | G12: 2º | H12: 4 | J12: 2º | K12: 4 | M12: 2º | N12: 4 | P12: 2º | Q12: 4
A13: Não Escalou | B13: 5 | D13: Não Escalou | E13: 5 | G13: Não Escalou | H13: 5 | J13: Não Escalou | K13: 5 | M13: Escalou | N13: 5 | P13: Não Escalou | Q13: 5
A14: Acessar o perfil do time Sempre ForteF.C. | B14: 6 | D14: Acessar o perfil do time LMD FC | E14: 6 | G14: Acessar o perfil do time PALM£IRAS S.E.P. | H14: 6 | J14: Acessar o perfil do time Bilao Sport FC | K14: 6 | M14: Acessar o perfil do time Andico F.C | N14: 6 | P14: Acessar o perfil do time AvantiPalestraFC | Q14: 6
B15: 7 | E15: 7 | H15: 7 | K15: 7 | N15: 7 | Q15: 7
A16: Sempre ForteF.C. | B16: 1 | D16: LMD FC | E16: 1 | G16: PALM£IRAS S.E.P. | H16: 1 | J16: Bilao Sport FC | K16: 1 | M16: Andico F.C | N16: 1 | P16: AvantiPalestraFC | Q16: 1
A17: Jonathan Oliveira de | B17: 2 | D17: Lucas Matias | E17: 2 | G17: Diego Longo | H17: 2 | J17: Gabriel Alencar | K17: 2 | M17: Leandro Souza | N17: 2 | P17: Tiago Matias Dias | Q17: 2
A18: 111.28 | B18: 3 | D18: C$ 184.78 | E18: 3 | G18: 115.44 | H18: 3 | J18: C$ 185.77 | K18: 3 | M18: 103.98 | N18: 3 | P18: C$ 185.48 | Q18: 3
A19: 3º | B19: 4 | D19: 3º | E19: 4 | G19: 3º | H19: 4 | J19: 3º | K19: 4 | M19: 3º | N19: 4 | P19: 3º | Q19: 4
A20: Não Escalou | B20: 5 | D20: Não Escalou | E20: 5 | G20: Escalou | H20: 5 | J20: Não Escalou | K20: 5 | M20: Não Escalou | N20: 5 | P20: Não Escalou | Q20: 5
A21: Acessar o perfil do time Mitinga`s F.C | B21: 6 | D21: Acessar o perfil do time Bilao Sport FC | E21: 6 | G21: Acessar o perfil do time HPano FC | H21: 6 | J21: Acessar o perfil do time LMD FC | K21: 6 | M21: Acessar o perfil do time CRPELUSO | N21: 6 | P21: Acessar o perfil do time APELÕES FUTEBOL CLUB | Q21: 6
B22: 7 | E22: 7 | H22: 7 | K22: 7 | N22: 7 | Q22: 7
A23: Mitinga`s F.C | B23: 1 | D23: Bilao Sport FC | E23: 1 | G23: HPano FC | H23: 1 | J23: LMD FC | K23: 1 | M23: CRPELUSO | N23: 1 | P23: APELÕES FUTEBOL CLUB | Q23: 1
A24: Marcel Cantalego | B24: 2 | D24: Gabriel Alencar | E24: 2 | G24: Henrique Panobianco | H24: 2 | J24: Lucas Matias | K24: 2 | M24: Claudio R Peluso | N24: 2 | P24: Greg Quirino | Q24: 2
A25: 106.98 | B25: 3 | D25: C$ 183.23 | E25: 3 | G25: 114.64 | H25: 3 | J25: C$ 185.53 | K25: 3 | M25: 103.96 | N25: 3 | P25: C$ 184.30 | Q25: 3
A26: 4º | B26: 4 | D26: 4º | E26: 4 | G26: 4º | H26: 4 | J26: 4º | K26: 4 | M26: 4º | N26: 4 | P26: 4º | Q26: 4
A27: Não Escalou | B27: 5 | D27: Não Escalou | E27: 5 | G27: Não Escalou | H27: 5 | J27: Não Escalou | K27: 5 | M27: Não Escalou | N27: 5 | P27: Não Escalou | Q27: 5
A28: Acessar o perfil do time PALM£IRAS S.E.P. | B28: 6 | D28: Acessar o perfil do time APELÕES FUTEBOL CLUB | E28: 6 | G28: Acessar o perfil do time Andico F.C | H28: 6 | J28: Acessar o perfil do time AvantiPalestraFC | K28: 6 | M28: Acessar o perfil do time Centenario Alviverde | N28: 6 | P28: Acessar o perfil do time Bilao Sport FC | Q28: 6
B29: 7 | E29: 7 | H29: 7 | K29: 7 | N29: 7 | Q29: 7
A30: PALM£IRAS S.E.P. | B30: 1 | D30: APELÕES FUTEBOL CLUB | E30: 1 | G30: Andico F.C | H30: 1 | J30: AvantiPalestraFC | K30: 1 | M30: Centenario Alviverde | N30: 1 | P30: Bilao Sport FC | Q30: 1
A31: Diego Longo | B31: 2 | D31: Greg Quirino | E31: 2 | G31: Leandro Souza | H31: 2 | J31: Tiago Matias Dias | K31: 2 | M31: Allan James | N31: 2 | P31: Gabriel Alencar | Q31: 2
A32: 106.88 | B32: 3 | D32: C$ 183.14 | E32: 3 | G32: 110.18 | H32: 3 | J32: C$ 183.98 | K32: 3 | M32: 99.66 | N32: 3 | P32: C$ 183.56 | Q32: 3
A33: 5º | B33: 4 | D33: 5º | E33: 4 | G33: 5º | H33: 4 | J33: 5º | K33: 4 | M33: 5º | N33: 4 | P33: 5º | Q33: 4
A34: Escalou | B34: 5 | D34: Não Escalou | E34: 5 | G34: Não Escalou | H34: 5 | J34: Não Escalou | K34: 5 | M34: Não Escalou | N34: 5 | P34: Não Escalou | Q34: 5
A35: Acessar o perfil do time Wedgol | B35: 6 | D35: Acessar o perfil do time Evans Jr FC | E35: 6 | G35: Acessar o perfil do time Mosby | H35: 6 | J35: Acessar o perfil do time Evans Jr FC | K35: 6 | M35: Acessar o perfil do time sccpguifc | N35: 6 | P35: Acessar o perfil do time Evans Jr FC | Q35: 6
B36: 7 | E36: 7 | H36: 7 | K36: 7 | N36: 7 | Q36: 7
A37: Wedgol | B37: 1 | D37: Evans Jr FC | E37: 1 | G37: Mosby | H37: 1 | J37: Evans Jr FC | K37: 1 | M37: sccpguifc | N37: 1 | P37: Evans Jr FC | Q37: 1
A38: Wedson da Silva | B38: 2 | D38: Evanil Junior | E38: 2 | G38: Felipe Rossi | H38: 2 | J38: Evanil Junior | K38: 2 | M38: Guilherme Vasconcelo | N38: 2 | P38: Evanil Junior | Q38: 2
A39: 106.38 | B39: 3 | D39: C$ 180.56 | E39: 3 | G39: 108.31 | H39: 3 | J39: C$ 182.19 | K39: 3 | M39: 97.45 | N39: 3 | P39: C$ 183.42 | Q39: 3
A40: 6º | B40: 4 | D40: 6º | E40: 4 | G40: 6º | H40: 4 | J40: 6º | K40: 4 | M40: 6º | N40: 4 | P40: 6º | Q40: 4
...

Sheet Colagem
A1: SE Coringas do Piero | B1: 117.54 | E1: Bilao Sport Club | F1: C$ 325.83 | H1: EmesuShow Porcolino | I1: 118.86 | K1: Bilao Sport Club | L1: C$ 326.99
A2: Gabirobense | B2: 115.78 | E2: APELÕES FUTEBOL CLUB | F2: C$ 185.79 | H2: Bike Cristo | I2: 107.66 | K2: LMD FC | L2: C$ 187.22
A3: PALM£IRAS S.E.P. | B3: 115.44 | E3: Bilao Sport FC | F3: C$ 185.77 | H3: Andico F.C | I3: 103.98 | K3: AvantiPalestraFC | L3: C$ 185.48
A4: HPano FC | B4: 114.64 | E4: LMD FC | F4: C$ 185.53 | H4: CRPELUSO | I4: 103.96 | K4: APELÕES FUTEBOL CLUB | L4: C$ 184.30
A5: Andico F.C | B5: 110.18 | E5: AvantiPalestraFC | F5: C$ 183.98 | H5: Centenario Alviverde | I5: 99.66 | K5: Bilao Sport FC | L5: C$ 183.56
A6: Mosby | B6: 108.31 | E6: Evans Jr FC | F6: C$ 182.19 | H6: sccpguifc | I6: 97.45 | K6: Evans Jr FC | L6: C$ 183.42
A7: Maletinhas F.C. | B7: 107.34 | E7: Coxinha Prime | F7: C$ 176.79 | H7: Pelicano Papada F.C | I7: 95.31 | K7: Coxinha Prime | L7: C$ 174.91
A8: GEJA | B8: 105.54 | E8: Metamoney F.C | F8: C$ 176.69 | H8: Amigos do Loco Abreu | I8: 94.86 | K8: Metamoney F.C | L8: C$ 174.58
A9: Brabo Globetrotters | B9: 102.94 | E9: Allejo Team F.C | F9: C$ 175.41 | H9: MC Formigão F.C | I9: 94.26 | K9: Mitinga`s F.C | L9: C$ 173.30
A10: Botafogo Hell | B10: 102.94 | E10: Mitinga`s F.C | F10: C$ 175.34 | H10: GIGANTES MORUMBI F.C | I10: 92.66 | K10: Andrétero FC | L10: C$ 173.09
A11: Sobottka FC 633 | B11: 102.24 | E11: PALM£IRAS S.E.P. | F11: C$ 174.78 | H11: Luket Wanderes fc | I11: 92.28 | K11: Allejo Team F.C | L11: C$ 172.89
A12: Tupinianos FC | B12: 101.24 | E12: Vuduzera | F12: C$ 173.99 | H12: Wedgol | I12: 92.15 | K12: PALM£IRAS S.E.P. | L12: C$ 172.29
... A83: S C Taleb Paulista | B83: 13.60 | E83: CR Pelég | F83: C$ 90.87 | H83: DuTurolla | I83: 21.01 | K83: CR Pelég | L83: C$ 90.39

Sheet base_cod_2026
A1: cod | B1: time | C1: P | D1: pts | E1: c | F1: cart | G1: x | H1: ano | I1: rodada | J1: cartola_time_id | K1: pontos | L1: patrimonio | M1: posicao | N1: xx | O1: =CONCATENATE(H1,",",I1,",",J1,",",K1,",",L1,",",M1) -> ano,rodada,cartola_time_id,pontos,patrimonio,posicao
A2: 53 | B2: EmesuShow Porcolino | C2: =VLOOKUP(B2,Colagem!H:I,2,FALSE) -> 118.86 | D2: =--SUBSTITUTE(C2, ".", ",") -> 118.86 | E2: =VLOOKUP(B2,Colagem!K:L,2,FALSE) -> C$ 140.93 | F2: =SUBSTITUTE(E2, "C$","") -> 140.93 | H2: 2026 | I2: 32 | J2: 53 | K2: =C2 -> 118.86 | L2: =TRIM(F2) -> 140.93 | M2: 1 | O2: =CONCATENATE(H2,",",I2,",",J2,",",K2,",",L2,",",M2) -> 2026,32,53,118.86,140.93,1
A3: 39 | B3: Bike Cristo | C3: =VLOOKUP(B3,Colagem!H:I,2,FALSE) -> 107.66 | D3: =--SUBSTITUTE(C3, ".", ",") -> 107.66 | E3: =VLOOKUP(B3,Colagem!K:L,2,FALSE) -> C$ 150.40 | F3: =SUBSTITUTE(E3, "C$","") -> 150.40 | H3: 2026 | I3: 32 | J3: 39 | K3: =C3 -> 107.66 | L3: =TRIM(F3) -> 150.40 | M3: 2 | O3: =CONCATENATE(H3,",",I3,",",J3,",",K3,",",L3,",",M3) -> 2026,32,39,107.66,150.40,2
A4: 31 | B4: Andico F.C | C4: =VLOOKUP(B4,Colagem!H:I,2,FALSE) -> 103.98 | D4: =--SUBSTITUTE(C4, ".", ",") -> 103.98 | E4: =VLOOKUP(B4,Colagem!K:L,2,FALSE) -> C$ 156.01 | F4: =SUBSTITUTE(E4, "C$","") -> 156.01 | H4: 2026 | I4: 32 | J4: 31 | K4: =C4 -> 103.98 | L4: =TRIM(F4) -> 156.01 | M4: 3 | O4: =CONCATENATE(H4,",",I4,",",J4,",",K4,",",L4,",",M4) -> 2026,32,31,103.98,156.01,3
A5: 17 | B5: CRPELUSO | C5: =VLOOKUP(B5,Colagem!H:I,2,FALSE) -> 103.96 | D5: =--SUBSTITUTE(C5, ".", ",") -> 103.96 | E5: =VLOOKUP(B5,Colagem!K:L,2,FALSE) -> C$ 163.46 | F5: =SUBSTITUTE(E5, "C$","") -> 163.46 | H5: 2026 | I5: 32 | J5: 17 | K5: =C5 -> 103.96 | L5: =TRIM(F5) -> 163.46 | M5: 4 | O5: =CONCATENATE(H5,",",I5,",",J5,",",K5,",",L5,",",M5) -> 2026,32,17,103.96,163.46,4
A6: 6 | B6: Centenario Alviverde | C6: =VLOOKUP(B6,Colagem!H:I,2,FALSE) -> 99.66 | D6: =--SUBSTITUTE(C6, ".", ",") -> 99.66 | E6: =VLOOKUP(B6,Colagem!K:L,2,FALSE) -> C$ 161.64 | F6: =SUBSTITUTE(E6, "C$","") -> 161.64 | H6: 2026 | I6: 32 | J6: 6 | K6: =C6 -> 99.66 | L6: =TRIM(F6) -> 161.64 | M6: 5 | O6: =CONCATENATE(H6,",",I6,",",J6,",",K6,",",L6,",",M6) -> 2026,32,6,99.66,161.64,5
A7: 82 | B7: sccpguifc | C7: =VLOOKUP(B7,Colagem!H:I,2,FALSE) -> 97.45 | D7: =--SUBSTITUTE(C7, ".", ",") -> 97.45 | E7: =VLOOKUP(B7,Colagem!K:L,2,FALSE) -> C$ 151.91 | F7: =SUBSTITUTE(E7, "C$","") -> 151.91 | H7: 2026 | I7: 32 | J7: 82 | K7: =C7 -> 97.45 | L7: =TRIM(F7) -> 151.91 | M7: 6 | O7: =CONCATENATE(H7,",",I7,",",J7,",",K7,",",L7,",",M7) -> 2026,32,82,97.45,151.91,6
A8: 71 | B8: Pelicano Papada F.C | C8: =VLOOKUP(B8,Colagem!H:I,2,FALSE) -> 95.31 | D8: =--SUBSTITUTE(C8, ".", ",") -> 95.31 | E8: =VLOOKUP(B8,Colagem!K:L,2,FALSE) -> C$ 141.14 | F8: =SUBSTITUTE(E8, "C$","") -> 141.14 | H8: 2026 | I8: 32 | J8: 71 | K8: =C8 -> 95.31 | L8: =TRIM(F8) -> 141.14 | M8: 7 | O8: =CONCATENATE(H8,",",I8,",",J8,",",K8,",",L8,",",M8) -> 2026,32,71,95.31,141.14,7
A9: 42 | B9: Amigos do Loco Abreu | C9: =VLOOKUP(B9,Colagem!H:I,2,FALSE) -> 94.86 | D9: =--SUBSTITUTE(C9, ".", ",") -> 94.86 | E9: =VLOOKUP(B9,Colagem!K:L,2,FALSE) -> C$ 160.22 | F9: =SUBSTITUTE(E9, "C$","") -> 160.22 | H9: 2026 | I9: 32 | J9: 42 | K9: =C9 -> 94.86 | L9: =TRIM(F9) -> 160.22 | M9: 8 | O9: =CONCATENATE(H9,",",I9,",",J9,",",K9,",",L9,",",M9) -> 2026,32,42,94.86,160.22,8
A10: 4 | B10: MC Formigão F.C | C10: =VLOOKUP(B10,Colagem!H:I,2,FALSE) -> 94.26 | D10: =--SUBSTITUTE(C10, ".", ",") -> 94.26 | E10: =VLOOKUP(B10,Colagem!K:L,2,FALSE) -> C$ 152.41 | F10: =SUBSTITUTE(E10, "C$","") -> 152.41 | H10: 2026 | I10: 32 | J10: 4 | K10: =C10 -> 94.26 | L10: =TRIM(F10) -> 152.41 | M10: 9 | O10: =CONCATENATE(H10,",",I10,",",J10,",",K10,",",L10,",",M10) -> 2026,32,4,94.26,152.41,9
A11: 44 | B11: GIGANTES MORUMBI F.C | C11: =VLOOKUP(B11,Colagem!H:I,2,FALSE) -> 92.66 | D11: =--SUBSTITUTE(C11, ".", ",") -> 92.66 | E11: =VLOOKUP(B11,Colagem!K:L,2,FALSE) -> C$ 162.80 | F11: =SUBSTITUTE(E11, "C$","") -> 162.80 | H11: 2026 | I11: 32 | J11: 44 | K11: =C11 -> 92.66 | L11: =TRIM(F11) -> 162.80 | M11: 10 | O11: =CONCATENATE(H11,",",I11,",",J11,",",K11,",",L11,",",M11) -> 2026,32,44,92.66,162.80,10
A12: 35 | B12: Luket Wanderes fc | C12: =VLOOKUP(B12,Colagem!H:I,2,FALSE) -> 92.28 | D12: =--SUBSTITUTE(C12, ".", ",") -> 92.28 | E12: =VLOOKUP(B12,Colagem!K:L,2,FALSE) -> C$ 156.35 | F12: =SUBSTITUTE(E12, "C$","") -> 156.35 | H12: 2026 | I12: 32 | J12: 35 | K12: =C12 -> 92.28 | L12: =TRIM(F12) -> 156.35 | M12: 11 | O12: =CONCATENATE(H12,",",I12,",",J12,",",K12,",",L12,",",M12) -> 2026,32,35,92.28,156.35,11
A13: 65 | B13: Wedgol | C13: =VLOOKUP(B13,Colagem!H:I,2,FALSE) -> 92.15 | D13: =--SUBSTITUTE(C13, ".", ",") -> 92.15 | E13: =VLOOKUP(B13,Colagem!K:L,2,FALSE) -> C$ 147.64 | F13: =SUBSTITUTE(E13, "C$","") -> 147.64 | H13: 2026 | I13: 32 | J13: 65 | K13: =C13 -> 92.15 | L13: =TRIM(F13) -> 147.64 | M13: 12 | O13: =CONCATENATE(H13,",",I13,",",J13,",",K13,",",L13,",",M13) -> 2026,32,65,92.15,147.64,12
... A84: 52 | B84: DuTurolla | C84: =VLOOKUP(B84,Colagem!H:I,2,FALSE) -> 21.01 | D84: =--SUBSTITUTE(C84, ".", ",") -> 21.01 | E84: =VLOOKUP(B84,Colagem!K:L,2,FALSE) -> C$ 98.86 | F84: =SUBSTITUTE(E84, "C$","") -> 98.86 | H84: 2026 | I84: 32 | J84: 52 | K84: =C84 -> 21.01 | L84: =TRIM(F84) -> 98.86 | M84: 83 | O84: =CONCATENATE(H84,",",I84,",",J84,",",K84,",",L84,",",M84) -> 2026,32,52,21.01,98.86,83

Sheet Planilha2
A1: a | B1: b
A2: ZAGO PRATIS FC | B2: 1 | E2: ZAGO PRATIS FC | G2: ZAGO PRATIS FC | H2: 1
A3: ANDRE PRATS | B3: 2 | E3: ANDRE PRATS | G3: ANDRE PRATS | H3: 2
A4: - | B4: 3 | E4: - | G4: - | H4: 3
A5: - | B5: 4 | E5: - | G5: - | H5: 4
A6: Não Escalou | B6: 5 | E6: Não Escalou | G6: Escalou | H6: 5
A7: Acessar o perfil do time Luket Wanderes fc | B7: 6 | E7: Acessar o perfil do time Luket Wanderes fc | G7: Acessar o perfil do time Luket Wanderes fc | H7: 6
B8: 7 | H8: 7
A9: Luket Wanderes fc | B9: 1 | E9: Luket Wanderes fc | G9: Luket Wanderes fc | H9: 1
A10: Lucas Silva Vieira | B10: 2 | E10: Lucas Silva Vieira | G10: Lucas Silva Vieira | H10: 2
A11: - | B11: 3 | E11: - | G11: - | H11: 3
A12: - | B12: 4 | E12: - | G12: - | H12: 4
A13: Não Escalou | B13: 5 | E13: Não Escalou | G13: Escalou | H13: 5
A14: Acessar o perfil do time FOI O QUE SOBROU | B14: 6 | E14: Acessar o perfil do time FOI O QUE SOBROU | G14: Acessar o perfil do time FOI O QUE SOBROU | H14: 6
B15: 7 | H15: 7
A16: FOI O QUE SOBROU | B16: 1 | E16: FOI O QUE SOBROU | G16: FOI O QUE SOBROU | H16: 1
A17: V. ÉDIPO | B17: 2 | E17: V. ÉDIPO | G17: V. ÉDIPO | H17: 2
A18: - | B18: 3 | E18: - | G18: - | H18: 3
A19: - | B19: 4 | E19: - | G19: - | H19: 4
A20: Escalou | B20: 5 | E20: Escalou | G20: Escalou | H20: 5
A21: Acessar o perfil do time CalazansTeam | B21: 6 | E21: Acessar o perfil do time CalazansTeam | G21: Acessar o perfil do time CalazansTeam | H21: 6
B22: 7 | H22: 7
A23: CalazansTeam | B23: 1 | E23: CalazansTeam | G23: CalazansTeam | H23: 1
A24: ALYSON | B24: 2 | E24: ALYSON | G24: ALYSON | H24: 2
A25: - | B25: 3 | E25: - | G25: - | H25: 3
A26: - | B26: 4 | E26: - | G26: - | H26: 4
A27: Não Escalou | B27: 5 | E27: Não Escalou | G27: Escalou | H27: 5
A28: Acessar o perfil do time CRPELUSO | B28: 6 | E28: Acessar o perfil do time CRPELUSO | G28: Acessar o perfil do time CRPELUSO | H28: 6
B29: 7 | H29: 7
A30: CRPELUSO | B30: 1 | E30: CRPELUSO | G30: CRPELUSO | H30: 1
A31: Claudio R Peluso | B31: 2 | E31: Claudio R Peluso | G31: Claudio R Peluso | H31: 2
A32: - | B32: 3 | E32: - | G32: - | H32: 3
A33: - | B33: 4 | E33: - | G33: - | H33: 4
A34: Escalou | B34: 5 | E34: Escalou | G34: Escalou | H34: 5
A35: Acessar o perfil do time PALM£IRAS S.E.P. | B35: 6 | E35: Acessar o perfil do time PALM£IRAS S.E.P. | G35: Acessar o perfil do time PALM£IRAS S.E.P. | H35: 6
B36: 7 | H36: 7
A37: PALM£IRAS S.E.P. | B37: 1 | E37: PALM£IRAS S.E.P. | G37: PALM£IRAS S.E.P. | H37: 1
A38: Diego Longo | B38: 2 | E38: Diego Longo | G38: Diego Longo | H38: 2
A39: - | B39: 3 | E39: - | G39: - | H39: 3
A40: - | B40: 4 | E40: - | G40: - | H40: 4
...

Sheet Planilha3
A1: Maletinhas F.C. | B1: X | C1: =VLOOKUP(A1,E:G,3,FALSE) -> Y | E1: ZAGO PRATIS FC | F1: =VLOOKUP(E1,A:B,2,FALSE) -> X | G1: Y
A2: Sobottka FC 633 | B2: X | C2: =VLOOKUP(A2,E:G,3,FALSE) -> Y | E2: Luket Wanderes fc | F2: =VLOOKUP(E2,A:B,2,FALSE) -> X | G2: Y
A3: GIGANTES MORUMBI F.C | B3: X | C3: =VLOOKUP(A3,E:G,3,FALSE) -> Y | E3: FOI O QUE SOBROU | F3: =VLOOKUP(E3,A:B,2,FALSE) -> X | G3: Y
A4: Adshow17 F.C | B4: X | C4: =VLOOKUP(A4,E:G,3,FALSE) -> Y | E4: CalazansTeam | F4: =VLOOKUP(E4,A:B,2,FALSE) -> X | G4: Y
A5: Schuletroll | B5: X | C5: =VLOOKUP(A5,E:G,3,FALSE) -> Y | E5: CRPELUSO | F5: =VLOOKUP(E5,A:B,2,FALSE) -> X | G5: Y
A6: CamisaNegra FC | B6: X | C6: =VLOOKUP(A6,E:G,3,FALSE) -> Y | E6: PALM£IRAS S.E.P. | F6: =VLOOKUP(E6,A:B,2,FALSE) -> X | G6: Y
A7: Mitinga`s F.C | B7: X | C7: =VLOOKUP(A7,E:G,3,FALSE) -> Y | E7: Bike Cristo | F7: =VLOOKUP(E7,A:B,2,FALSE) -> X | G7: Y
A8: FOI O QUE SOBROU | B8: X | C8: =VLOOKUP(A8,E:G,3,FALSE) -> Y | E8: Ferrugem Ultimate | F8: =VLOOKUP(E8,A:B,2,FALSE) -> X | G8: Y
A9: Vuduzera | B9: X | C9: =VLOOKUP(A9,E:G,3,FALSE) -> Y | E9: E.C. Ocram 5.6 | F9: =VLOOKUP(E9,A:B,2,FALSE) -> X | G9: Y
A10: ZEKABOLEIRO | B10: X | C10: =VLOOKUP(A10,E:G,3,FALSE) -> Y | E10: Maletinhas F.C. | F10: =VLOOKUP(E10,A:B,2,FALSE) -> X | G10: Y
A11: EmesuShow Porcolino | B11: X | C11: =VLOOKUP(A11,E:G,3,FALSE) -> Y | E11: 08 Ratto FC | F11: =VLOOKUP(E11,A:B,2,FALSE) -> X | G11: Y
A12: TIMAO R.F.G | B12: X | C12: =VLOOKUP(A12,E:G,3,FALSE) -> Y | E12: Real Rattaria FC | F12: =VLOOKUP(E12,A:B,2,FALSE) -> X | G12: Y
... A80: Lanterninha Futebol Clube | B80: X | C80: =VLOOKUP(A80,E:G,3,FALSE) -> Y | E80: A D Peaky Blinders | F80: =VLOOKUP(E80,A:B,2,FALSE) -> #N/A | G80: Y

Sheet ORG
A1: TIME | B1: CARTOLEIRO | C1: ORD | D1: ID | E1: nome | F1: ID | G1: X | H1: ID_time | I1: ID_CART | J1: NOME_TIME | K1: TEMPORADA | L1: DIV 2025 | M1: pos | N1: st | O1: DIV 2026 P | P1: DIV 2026 D | Q1: status[ | R1: X | S1: id_d | T1: time_id | U1: divisao_id | V1: temp | W1: ativo | Y1: id_fk | Z1: apelido | AA1: telefone | AB1: time coracao | AC1: cidade | AD1: estado | AE1: pais
A2: Maletinhas F.C. | B2: Ricardo | C2: 2 | E2: R MALETA | F2: 41 | H2: 41 | I2: 41 | J2: Maletinhas F.C. | K2: 2026 | L2: =VLOOKUP(J2,SERIES!B:K,10,FALSE) -> A | M2: =VLOOKUP(J2,SERIES!B:K,2,FALSE) -> 1 | N2: =VLOOKUP(J2,SERIES!B:K,9,FALSE) -> C | O2: A | P2: A | Q2: 2025 | T2: =H2 -> 41 | U2: 1 | V2: 2026 | W2: true
A3: Sobottka FC 633 | B3: Gustavo Sobottka | C3: 2 | E3: G SOBOTTKA | F3: 26 | H3: 26 | I3: 26 | J3: Sobottka FC 633 | K3: 2026 | L3: =VLOOKUP(J3,SERIES!B:K,10,FALSE) -> A | M3: =VLOOKUP(J3,SERIES!B:K,2,FALSE) -> 2 | N3: =VLOOKUP(J3,SERIES!B:K,9,FALSE) -> M | O3: A | P3: A | Q3: 2025 | T3: =H3 -> 26 | U3: 1 | V3: 2026 | W3: true
A4: GIGANTES MORUMBI F.C | B4: Sergio Garcia | C4: 2 | E4: S GARCIA | F4: 44 | H4: 44 | I4: 44 | J4: GIGANTES MORUMBI F.C | K4: 2026 | L4: =VLOOKUP(J4,SERIES!B:K,10,FALSE) -> A | M4: =VLOOKUP(J4,SERIES!B:K,2,FALSE) -> 3 | N4: =VLOOKUP(J4,SERIES!B:K,9,FALSE) -> M | O4: A | P4: A | Q4: 2025 | T4: =H4 -> 44 | U4: 1 | V4: 2026 | W4: true
A5: Adshow17 F.C | B5: Adson Mendes | C5: 2 | E5: ADSON | F5: 3 | H5: 3 | I5: 3 | J5: Adshow17 F.C | K5: 2026 | L5: =VLOOKUP(J5,SERIES!B:K,10,FALSE) -> A | M5: =VLOOKUP(J5,SERIES!B:K,2,FALSE) -> 4 | N5: =VLOOKUP(J5,SERIES!B:K,9,FALSE) -> M | O5: A | P5: A | Q5: 2025 | T5: =H5 -> 3 | U5: 1 | V5: 2026 | W5: true
A6: Schuletroll | B6: Leandro Schulai | C6: 6 | E6: SCHULETA | F6: 67 | H6: 70 | I6: 67 | J6: Schuletroll | K6: 2026 | L6: =VLOOKUP(J6,SERIES!B:K,10,FALSE) -> A | M6: =VLOOKUP(J6,SERIES!B:K,2,FALSE) -> 5 | N6: =VLOOKUP(J6,SERIES!B:K,9,FALSE) -> M | O6: A | P6: A | Q6: 2025 | T6: =H6 -> 70 | U6: 1 | V6: 2026 | W6: true
A7: CamisaNegra FC | B7: Lissão | C7: 2 | E7: LISSAO | F7: 32 | H7: 32 | I7: 32 | J7: CamisaNegra FC | K7: 2026 | L7: A | M7: 6 | N7: M | O7: A | P7: A | Q7: 2025 | T7: =H7 -> 32 | U7: 1 | V7: 2026 | W7: true
A8: Mitinga`s F.C | B8: Marcel Cantalego | C8: 2 | E8: M CANTALEGO | F8: 37 | H8: 37 | I8: 37 | J8: Mitinga`s F.C | K8: 2026 | L8: =VLOOKUP(J8,SERIES!B:K,10,FALSE) -> A | M8: =VLOOKUP(J8,SERIES!B:K,2,FALSE) -> 7 | N8: =VLOOKUP(J8,SERIES!B:K,9,FALSE) -> M | O8: A | P8: A | Q8: 2025 | T8: =H8 -> 37 | U8: 1 | V8: 2026 | W8: true
A9: FOI O QUE SOBROU | B9: V. ÉDIPO | C9: 2 | E9: EDIPO | F9: 47 | H9: 47 | I9: 47 | J9: FOI O QUE SOBROU | K9: 2026 | L9: =VLOOKUP(J9,SERIES!B:K,10,FALSE) -> A | M9: =VLOOKUP(J9,SERIES!B:K,2,FALSE) -> 8 | N9: =VLOOKUP(J9,SERIES!B:K,9,FALSE) -> M | O9: A | P9: A | Q9: 2025 | T9: =H9 -> 47 | U9: 1 | V9: 2026 | W9: true
A10: Vuduzera | B10: Vudu | C10: 2 | E10: VUDU | F10: 63 | H10: 63 | I10: 63 | J10: Vuduzera | K10: 2026 | L10: =VLOOKUP(J10,SERIES!B:K,10,FALSE) -> A | M10: =VLOOKUP(J10,SERIES!B:K,2,FALSE) -> 9 | N10: =VLOOKUP(J10,SERIES!B:K,9,FALSE) -> M | O10: A | P10: A | Q10: 2025 | T10: =H10 -> 63 | U10: 1 | V10: 2026 | W10: true
A11: ZEKABOLEIRO | B11: TRIPA | C11: 2 | E11: R TRIPAO | F11: 61 | H11: 61 | I11: 61 | J11: ZEKABOLEIRO | K11: 2026 | L11: =VLOOKUP(J11,SERIES!B:K,10,FALSE) -> A | M11: =VLOOKUP(J11,SERIES!B:K,2,FALSE) -> 10 | N11: =VLOOKUP(J11,SERIES!B:K,9,FALSE) -> M | O11: A | P11: A | Q11: 2025 | T11: =H11 -> 61 | U11: 1 | V11: 2026 | W11: true
A12: EmesuShow Porcolino | B12: Emerson Rocha | C12: 2 | E12: PORCOLINO | F12: 53 | H12: 53 | I12: 53 | J12: EmesuShow Porcolino | K12: 2026 | L12: =VLOOKUP(J12,SERIES!B:K,10,FALSE) -> A | M12: =VLOOKUP(J12,SERIES!B:K,2,FALSE) -> 12 | N12: =VLOOKUP(J12,SERIES!B:K,9,FALSE) -> M | O12: A | P12: A | Q12: 2025 | T12: =H12 -> 53 | U12: 1 | V12: 2026 | W12: true
A13: TIMAO R.F.G | B13: ROBSON CUNHA | C13: 2 | E13: R CUNHA | F13: 43 | H13: 43 | I13: 43 | J13: TIMAO R.F.G | K13: 2026 | L13: A | M13: 13 | N13: M | O13: A | P13: A | Q13: 2025 | T13: =H13 -> 43 | U13: 1 | V13: 2026 | W13: true
A14: PALM£IRAS S.E.P. | B14: Diego Longo | C14: 2 | E14: D LONGO | F14: 18 | H14: 18 | I14: 18 | J14: PALM£IRAS S.E.P. | K14: 2026 | L14: A | M14: 14 | N14: M | O14: A | P14: A | Q14: 2025 | T14: =H14 -> 18 | U14: 1 | V14: 2026 | W14: true
A15: ZAGO PRATIS FC | B15: ANDRE PRATS | C15: 1 | E15: PRATIS | F15: 1 | H15: 1 | I15: 1 | J15: ZAGO PRATIS FC | K15: 2026 | L15: A | M15: 16 | N15: M | O15: A | P15: A | Q15: 2025 | T15: =H15 -> 1 | U15: 1 | V15: 2026 | W15: true
A16: Luket Wanderes fc | B16: Lucas Silva Vieira | C16: 2 | E16: LUKET | F16: 35 | H16: 35 | I16: 35 | J16: Luket Wanderes fc | K16: 2026 | L16: =VLOOKUP(J16,SERIES!B:K,10,FALSE) -> B | M16: =VLOOKUP(J16,SERIES!B:K,2,FALSE) -> 21 | N16: =VLOOKUP(J16,SERIES!B:K,9,FALSE) -> P | O16: A | P16: A | Q16: 2025 | T16: =H16 -> 35 | U16: 1 | V16: 2026 | W16: true
A17: Amigos do Loco Abreu | B17: Ricardo Filgueiras | C17: 2 | E17: R FILGUEIRAS | F17: 42 | H17: 42 | I17: 42 | J17: Amigos do Loco Abreu | K17: 2026 | L17: =VLOOKUP(J17,SERIES!B:K,10,FALSE) -> B | M17: =VLOOKUP(J17,SERIES!B:K,2,FALSE) -> 22 | N17: =VLOOKUP(J17,SERIES!B:K,9,FALSE) -> P | O17: A | P17: A | Q17: 2025 | T17: =H17 -> 42 | U17: 1 | V17: 2026 | W17: true
A18: Metamoney F.C | B18: Marcio Vieira | C18: 2 | E18: M VIEIRA | F18: 38 | H18: 38 | I18: 38 | J18: Metamoney F.C | K18: 2026 | L18: =VLOOKUP(J18,SERIES!B:K,10,FALSE) -> B | M18: =VLOOKUP(J18,SERIES!B:K,2,FALSE) -> 23 | N18: =VLOOKUP(J18,SERIES!B:K,9,FALSE) -> P | O18: A | P18: A | Q18: 2025 | T18: =H18 -> 38 | U18: 1 | V18: 2026 | W18: true
A19: Silasbrs FC | B19: Silas Siqueira | C19: 2 | E19: S SIQUEIRA | F19: 45 | H19: 45 | I19: 45 | J19: Silasbrs FC | K19: 2026 | L19: =VLOOKUP(J19,SERIES!B:K,10,FALSE) -> B | M19: =VLOOKUP(J19,SERIES!B:K,2,FALSE) -> 24 | N19: =VLOOKUP(J19,SERIES!B:K,9,FALSE) -> P | O19: A | P19: A | Q19: 2025 | T19: =H19 -> 45 | U19: 1 | V19: 2026 | W19: true
A20: Os Porko é Loko - Z/O | B20: Anderson Nogueira | C20: 2 | E20: A NOGUEIRA | F20: 10 | H20: 10 | I20: 10 | J20: Os Porko é Loko - Z/O | K20: 2026 | L20: =VLOOKUP(J20,SERIES!B:K,10,FALSE) -> B | M20: =VLOOKUP(J20,SERIES!B:K,2,FALSE) -> 25 | N20: =VLOOKUP(J20,SERIES!B:K,9,FALSE) -> M | O20: B | P20: A | Q20: 2025 | T20: =H20 -> 10 | U20: 1 | V20: 2026 | W20: true
A21: CRPELUSO | B21: Claudio R Peluso | C21: 2 | E21: C PELUSO | F21: 17 | H21: 17 | I21: 17 | J21: CRPELUSO | K21: 2026 | L21: =VLOOKUP(J21,SERIES!B:K,10,FALSE) -> B | M21: =VLOOKUP(J21,SERIES!B:K,2,FALSE) -> 26 | N21: =VLOOKUP(J21,SERIES!B:K,9,FALSE) -> M | O21: B | P21: A | Q21: 2025 | T21: =H21 -> 17 | U21: 1 | V21: 2026 | W21: true
A22: Ipanema13 | B22: Alexandre Carlos | C22: 2 | E22: ALE CHINELO | F22: 5 | H22: 5 | I22: 5 | J22: Ipanema13 | K22: 2026 | L22: =VLOOKUP(J22,SERIES!B:K,10,FALSE) -> A | M22: =VLOOKUP(J22,SERIES!B:K,2,FALSE) -> 17 | N22: =VLOOKUP(J22,SERIES!B:K,9,FALSE) -> R | O22: B | P22: B | Q22: 2025 | T22: =H22 -> 5 | U22: 2 | V22: 2026 | W22: true
A23: OtoPat@ma | B23: Paulo | C23: 2 | E23: P OTO | F23: 57 | H23: 57 | I23: 57 | J23: OtoPat@ma | K23: 2026 | L23: =VLOOKUP(J23,SERIES!B:K,10,FALSE) -> A | M23: =VLOOKUP(J23,SERIES!B:K,2,FALSE) -> 18 | N23: =VLOOKUP(J23,SERIES!B:K,9,FALSE) -> R | O23: B | P23: B | Q23: 2025 | T23: =H23 -> 57 | U23: 2 | V23: 2026 | W23: true
A24: Brabo Globetrotters | B24: Eduardo Brabo | C24: 2 | E24: BRABO | F24: 21 | H24: 21 | I24: 21 | J24: Brabo Globetrotters | K24: 2026 | L24: =VLOOKUP(J24,SERIES!B:K,10,FALSE) -> A | M24: =VLOOKUP(J24,SERIES!B:K,2,FALSE) -> 19 | N24: =VLOOKUP(J24,SERIES!B:K,9,FALSE) -> R | O24: B | P24: B | Q24: 2025 | T24: =H24 -> 21 | U24: 2 | V24: 2026 | W24: true
A25: Abóbora Futebol C | B25: Wellyngton Remesso | C25: 2 | E25: Abobora | F25: 69 | H25: 74 | I25: 69 | J25: Abóbora Futebol C | K25: 2026 | L25: =VLOOKUP(J25,SERIES!B:K,10,FALSE) -> A | M25: 20 | N25: =VLOOKUP(J25,SERIES!B:K,9,FALSE) -> R | O25: B | P25: B | Q25: 2025 | T25: =H25 -> 74 | U25: 2 | V25: 2026 | W25: true
A26: Sempre ForteF.C. | B26: Jonathan Oliveira de | C26: 2 | E26: BATATA | F26: 30 | H26: 30 | I26: 30 | J26: Sempre ForteF.C. | K26: 2026 | L26: =VLOOKUP(J26,SERIES!B:K,10,FALSE) -> B | M26: =VLOOKUP(J26,SERIES!B:K,2,FALSE) -> 27 | N26: =VLOOKUP(J26,SERIES!B:K,9,FALSE) -> M | O26: B | P26: B | Q26: 2025 | T26: =H26 -> 30 | U26: 2 | V26: 2026 | W26: true
A27: Ferrugem Ultimate | B27: Thiago Ribas | C27: 2 | E27: T RIBAS | F27: 46 | H27: 46 | I27: 46 | J27: Ferrugem Ultimate | K27: 2026 | L27: =VLOOKUP(J27,SERIES!B:K,10,FALSE) -> B | M27: =VLOOKUP(J27,SERIES!B:K,2,FALSE) -> 28 | N27: =VLOOKUP(J27,SERIES!B:K,9,FALSE) -> M | O27: B | P27: B | Q27: 2025 | T27: =H27 -> 46 | U27: 2 | V27: 2026 | W27: true
A28: 08 Ratto FC | B28: Gabriel Ratto2 | C28: 5 | E28: G RATTO | F28: 66 | H28: 69 | I28: 66 | J28: 08 Ratto FC | K28: 2026 | L28: =VLOOKUP(J28,SERIES!B:K,10,FALSE) -> B | M28: =VLOOKUP(J28,SERIES!B:K,2,FALSE) -> 29 | N28: =VLOOKUP(J28,SERIES!B:K,9,FALSE) -> M | O28: B | P28: B | Q28: 2025 | T28: =H28 -> 69 | U28: 2 | V28: 2026 | W28: true
A29: GEJA | B29: Wedgol | C29: 3 | E29: WED | F29: 64 | H29: 64 | I29: 64 | J29: GEJA | K29: 2026 | L29: =VLOOKUP(J29,SERIES!B:K,10,FALSE) -> B | M29: =VLOOKUP(J29,SERIES!B:K,2,FALSE) -> 30 | N29: =VLOOKUP(J29,SERIES!B:K,9,FALSE) -> M | O29: B | P29: B | Q29: 2025 | T29: =H29 -> 64 | U29: 2 | V29: 2026 | W29: true
A30: FUCKER AND SUCKER FC | B30: Veron | C30: 2 | E30: VERON | F30: 62 | H30: 62 | I30: 62 | J30: FUCKER AND SUCKER FC | K30: 2026 | L30: =VLOOKUP(J30,SERIES!B:K,10,FALSE) -> B | M30: =VLOOKUP(J30,SERIES!B:K,2,FALSE) -> 32 | N30: =VLOOKUP(J30,SERIES!B:K,9,FALSE) -> M | O30: B | P30: B | Q30: 2025 | T30: =H30 -> 62 | U30: 2 | V30: 2026 | W30: true
A31: SC Ornaghi Paulista | B31: Eduardo Ribas | C31: 2 | E31: ORNAGHI | F31: 22 | H31: 22 | I31: 22 | J31: SC Ornaghi Paulista | K31: 2026 | L31: =VLOOKUP(J31,SERIES!B:K,10,FALSE) -> B | M31: =VLOOKUP(J31,SERIES!B:K,2,FALSE) -> 33 | N31: =VLOOKUP(J31,SERIES!B:K,9,FALSE) -> M | O31: B | P31: B | Q31: 2025 | T31: =H31 -> 22 | U31: 2 | V31: 2026 | W31: true
A32: Massiminismo FC | B32: Lucas Massimini | C32: 2 | E32: L MASSIMINI | F32: 33 | H32: 33 | I32: 33 | J32: Massiminismo FC | K32: 2026 | L32: =VLOOKUP(J32,SERIES!B:K,10,FALSE) -> B | M32: =VLOOKUP(J32,SERIES!B:K,2,FALSE) -> 35 | N32: =VLOOKUP(J32,SERIES!B:K,9,FALSE) -> M | O32: B | P32: B | Q32: 2025 | T32: =H32 -> 33 | U32: 2 | V32: 2026 | W32: true
A33: Bilao Sport Club | B33: Gabriel Alencar | C33: 4 | E33: G ALENCAR | F33: 65 | H33: 67 | I33: 65 | J33: Bilao Sport Club | K33: 2026 | L33: =VLOOKUP(J33,SERIES!B:K,10,FALSE) -> B | M33: =VLOOKUP(J33,SERIES!B:K,2,FALSE) -> 36 | N33: =VLOOKUP(J33,SERIES!B:K,9,FALSE) -> M | O33: B | P33: B | Q33: 2025 | T33: =H33 -> 67 | U33: 2 | V33: 2026 | W33: true
A34: Botafogo Hell | B34: Gabriel | C34: 2 | E34: G BOTAFOGO | F34: 24 | H34: 24 | I34: 24 | J34: Botafogo Hell | K34: 2026 | L34: =VLOOKUP(J34,SERIES!B:K,10,FALSE) -> C | M34: =VLOOKUP(J34,SERIES!B:K,2,FALSE) -> 41 | N34: =VLOOKUP(J34,SERIES!B:K,9,FALSE) -> P | O34: B | P34: B | Q34: 2025 | T34: =H34 -> 24 | U34: 2 | V34: 2026 | W34: true
A35: Bike Cristo | B35: Maurício Silva | C35: 2 | E35: VEIO DA LARANJA | F35: 39 | H35: 39 | I35: 39 | J35: Bike Cristo | K35: 2026 | L35: =VLOOKUP(J35,SERIES!B:K,10,FALSE) -> C | M35: =VLOOKUP(J35,SERIES!B:K,2,FALSE) -> 42 | N35: =VLOOKUP(J35,SERIES!B:K,9,FALSE) -> P | O35: B | P35: B | Q35: 2025 | T35: =H35 -> 39 | U35: 2 | V35: 2026 | W35: true
A36: J.V.Finhani | B36: Jefferson Finhani | C36: 2 | E36: J FINHANI | F36: 28 | H36: 28 | I36: 28 | J36: J.V.Finhani | K36: 2026 | L36: =VLOOKUP(J36,SERIES!B:K,10,FALSE) -> C | M36: =VLOOKUP(J36,SERIES!B:K,2,FALSE) -> 43 | N36: =VLOOKUP(J36,SERIES!B:K,9,FALSE) -> P | O36: B | P36: B | Q36: 2025 | T36: =H36 -> 28 | U36: 2 | V36: 2026 | W36: true
A37: Adriano ZIZU | B37: Adriano Monteiro | C37: 2 | E37: A ZIZU | F37: 2 | H37: 2 | I37: 2 | J37: Adriano ZIZU | K37: 2026 | L37: =VLOOKUP(J37,SERIES!B:K,10,FALSE) -> C | M37: =VLOOKUP(J37,SERIES!B:K,2,FALSE) -> 45 | N37: =VLOOKUP(J37,SERIES!B:K,9,FALSE) -> M | O37: C | P37: B | Q37: 2025 | T37: =H37 -> 2 | U37: 2 | V37: 2026 | W37: true
... A44: Almi Jr. FC | B44: Almi Jr. | C44: 2 | E44: ALMI | F44: 8 | H44: 8 | I44: 8 | J44: Almi Jr. FC | K44: 2026 | L44: =VLOOKUP(J44,SERIES!B:K,10,FALSE) -> B | M44: =VLOOKUP(J44,SERIES!B:K,2,FALSE) -> 39 | N44: =VLOOKUP(J44,SERIES!B:K,9,FALSE) -> R | O44: C | P44: C | Q44: 2025 | T44: =H44 -> 8 | U44: 3 | V44: 2026 | W44: true
A45: Borussia do Jaguaré | B45: Rogério Lagos | C45: 2 | E45: LAGOS | F45: 59 | H45: 59 | I45: 59 | J45: Borussia do Jaguaré | K45: 2026 | L45: C | M45: 51 | N45: M | O45: C | P45: C | Q45: 2025 | T45: =H45 -> 59 | U45: 3 | V45: 2026 | W45: true
A46: Xuchélides | B46: Chélide Teixeira | C46: 2 | E46: C TEIXEIRA | F46: 16 | H46: 16 | I46: 16 | J46: Xuchélides | K46: 2026 | L46: =VLOOKUP(J46,SERIES!B:K,10,FALSE) -> C | M46: =VLOOKUP(J46,SERIES!B:K,2,FALSE) -> 52 | N46: =VLOOKUP(J46,SERIES!B:K,9,FALSE) -> M | O46: C | P46: C | Q46: 2025 | T46: =H46 -> 16 | U46: 3 | V46: 2026 | W46: true
...

Sheet SERIES
J1: ST | P1: NOME_TIME | Q1: DIV 2025 | R1: POSICAO EM 2025 | S1: DIV 2026 D | T1: MOTIVO | U1: status[
A2: A | B2: Maletinhas F.C. | C2: 1 | D2: RICARDO MALETA | E2: 81 | F2: 29 | G2: 0 | H2: 9 | I2: 3262.38 | J2: C | K2: A | L2: =VLOOKUP(B2,ORG!J:K,2,FALSE) -> 2026 | P2: Maletinhas F.C. | Q2: A | R2: 1 | S2: A | T2: FICOU NA SERIE | U2: 2025
A3: A | B3: Sobottka FC 633 | C3: 2 | D3: GUSTAVO NERY | E3: 65 | F3: 23 | G3: 0 | H3: 15 | I3: 3291.58 | J3: M | K3: A | L3: =VLOOKUP(B3,ORG!J:K,2,FALSE) -> 2026 | P3: Sobottka FC 633 | Q3: A | R3: 2 | S3: A | T3: FICOU NA SERIE | U3: 2025
A4: A | B4: GIGANTES MORUMBI F.C | C4: 3 | D4: SERGIO GARCIA | E4: 62 | F4: 23 | G4: 0 | H4: 15 | I4: 3235.59 | J4: M | K4: A | L4: =VLOOKUP(B4,ORG!J:K,2,FALSE) -> 2026 | P4: GIGANTES MORUMBI F.C | Q4: A | R4: 3 | S4: A | T4: FICOU NA SERIE | U4: 2025
A5: A | B5: Adshow17 F.C | C5: 4 | D5: ADSON MENDES | E5: 60 | F5: 21 | G5: 0 | H5: 17 | I5: 3222.62 | J5: M | K5: A | L5: =VLOOKUP(B5,ORG!J:K,2,FALSE) -> 2026 | P5: Adshow17 F.C | Q5: A | R5: 4 | S5: A | T5: FICOU NA SERIE | U5: 2025
A6: A | B6: Schuletroll | C6: 5 | D6: SCHULAI 1 | E6: 60 | F6: 21 | G6: 0 | H6: 17 | I6: 3052.98 | J6: M | K6: A | L6: =VLOOKUP(B6,ORG!J:K,2,FALSE) -> 2026 | P6: Schuletroll | Q6: A | R6: 5 | S6: A | T6: FICOU NA SERIE | U6: 2025
A7: A | B7: LissaoCruzmaltino FC | C7: 6 | D7: LISSAO | E7: 59 | F7: 21 | G7: 0 | H7: 17 | I7: 3181.07 | J7: M | K7: A | L7: 2026 | P7: CamisaNegra FC | Q7: A | R7: 6 | S7: A | T7: FICOU NA SERIE | U7: 2025
A8: A | B8: Mitinga`s F.C | C8: 7 | D8: MARCEL CANTALEGO | E8: 58 | F8: 20 | G8: 0 | H8: 18 | I8: 3291.53 | J8: M | K8: A | L8: =VLOOKUP(B8,ORG!J:K,2,FALSE) -> 2026 | P8: Mitinga`s F.C | Q8: A | R8: 7 | S8: A | T8: FICOU NA SERIE | U8: 2025
A9: A | B9: FOI O QUE SOBROU | C9: 8 | D9: EDIPO MACEDO | E9: 55 | F9: 20 | G9: 0 | H9: 18 | I9: 3278.83 | J9: M | K9: A | L9: =VLOOKUP(B9,ORG!J:K,2,FALSE) -> 2026 | P9: FOI O QUE SOBROU | Q9: A | R9: 8 | S9: A | T9: FICOU NA SERIE | U9: 2025
A10: A | B10: Vuduzera | C10: 9 | D10: VUDU | E10: 54 | F10: 19 | G10: 0 | H10: 19 | I10: 3197.48 | J10: M | K10: A | L10: =VLOOKUP(B10,ORG!J:K,2,FALSE) -> 2026 | P10: Vuduzera | Q10: A | R10: 9 | S10: A | T10: FICOU NA SERIE | U10: 2025
A11: A | B11: ZEKABOLEIRO | C11: 10 | D11: RICARDO TRIPAO | E11: 54 | F11: 19 | G11: 0 | H11: 19 | I11: 3120.55 | J11: M | K11: A | L11: =VLOOKUP(B11,ORG!J:K,2,FALSE) -> 2026 | P11: ZEKABOLEIRO | Q11: A | R11: 10 | S11: A | T11: FICOU NA SERIE | U11: 2025
A12: A | B12: #Santos.Z/O | C12: 11 | D12: ALLAN SANTOS | E12: 53 | F12: 20 | G12: 0 | H12: 18 | I12: 3141.74 | J12: M | K12: A | L12: =VLOOKUP(B12,ORG!J:K,2,FALSE) -> #N/A | P12: EmesuShow Porcolino | Q12: A | R12: 12 | S12: A | T12: FICOU NA SERIE | U12: 2025
A13: A | B13: EmesuShow Porcolino | C13: 12 | D13: EMERSON PORCOLINO | E13: 52 | F13: 19 | G13: 0 | H13: 19 | I13: 3106.05 | J13: M | K13: A | L13: =VLOOKUP(B13,ORG!J:K,2,FALSE) -> 2026 | P13: TIMAO R.F.G | Q13: A | R13: 13 | S13: A | T13: FICOU NA SERIE | U13: 2025
A14: A | B14: RCUNHA S.C.C.P | C14: 13 | D14: ROBSON CUNHA | E14: 49 | F14: 17 | G14: 0 | H14: 21 | I14: 3115.84 | J14: M | K14: A | L14: 2026 | P14: PALM£IRAS S.E.P. | Q14: A | R14: 14 | S14: A | T14: FICOU NA SERIE | U14: 2025
A15: A | B15: Paleztra's Club | C15: 14 | D15: DIEGO PALMEIRESEN | E15: 48 | F15: 18 | G15: 0 | H15: 20 | I15: 3167.06 | J15: M | K15: A | L15: 2026 | P15: ZAGO PRATIS FC | Q15: A | R15: 16 | S15: A | T15: FICOU NA SERIE | U15: 2025
A16: A | B16: A.C. Fontana | C16: 15 | D16: ANDRE FONTANA | E16: 48 | F16: 18 | G16: 0 | H16: 20 | I16: 3121.49 | J16: M | K16: A | L16: =VLOOKUP(B16,ORG!J:K,2,FALSE) -> #N/A | P16: Luket Wanderes fc | Q16: B | R16: 21 | S16: A | T16: VAGA DIRETA | U16: 2025
A17: A | B17: REAL SARANDI CLUBE | C17: 16 | D17: ANDRE PRATS | E17: 46 | F17: 17 | G17: 0 | H17: 21 | I17: 2924.75 | J17: M | K17: A | L17: 2026 | P17: Amigos do Loco Abreu | Q17: B | R17: 22 | S17: A | T17: VAGA DIRETA | U17: 2025
A18: A | B18: Ipanema13 | C18: 17 | D18: ALEXANDRE IPANEMA | E18: 42 | F18: 16 | G18: 0 | H18: 22 | I18: 3190.84 | J18: R | K18: A | L18: =VLOOKUP(B18,ORG!J:K,2,FALSE) -> 2026 | P18: Metamoney F.C | Q18: B | R18: 23 | S18: A | T18: VAGA DIRETA | U18: 2025
A19: A | B19: OtoPat@ma | C19: 18 | D19: PAULO OTO | E19: 42 | F19: 15 | G19: 0 | H19: 23 | I19: 2970.04 | J19: R | K19: A | L19: =VLOOKUP(B19,ORG!J:K,2,FALSE) -> 2026 | P19: Silasbrs FC | Q19: B | R19: 24 | S19: A | T19: VAGA DIRETA | U19: 2025
A20: A | B20: Brabo Globetrotters | C20: 19 | D20: EDUARDO BRABO | E20: 41 | F20: 15 | G20: 0 | H20: 23 | I20: 2969.69 | J20: R | K20: A | L20: =VLOOKUP(B20,ORG!J:K,2,FALSE) -> 2026 | P20: Os Porko é Loko - Z/O | Q20: B | R20: 25 | S20: A | T20: VAGA POR DESISTENCIA | U20: 2025
A21: A | B21: Abóbora Futebol C | C21: 20 | D21: WELLIGTON ABOBORA | E21: 25 | F21: 9 | G21: 0 | H21: 29 | I21: 2472.85 | J21: R | K21: A | L21: =VLOOKUP(B21,ORG!J:K,2,FALSE) -> 2026 | P21: CRPELUSO | Q21: B | R21: 26 | S21: A | T21: VAGA POR DESISTENCIA | U21: 2025
P22: Ipanema13 | Q22: A | R22: 17 | S22: B | T22: REBAIXADO | U22: 2025
A23: B | B23: Luket Wanderes fc | C23: 21 | D23: LUCAT | E23: 78 | F23: 26 | G23: 1 | H23: 11 | I23: 3253.38 | J23: P | K23: B | L23: =VLOOKUP(B23,ORG!J:K,2,FALSE) -> 2026 | P23: OtoPat@ma | Q23: A | R23: 18 | S23: B | T23: REBAIXADO | U23: 2025
A24: B | B24: Amigos do Loco Abreu | C24: 22 | D24: RICARDO FILGUEIRAS | E24: 71 | F24: 26 | G24: 0 | H24: 12 | I24: 3224.90 | J24: P | K24: B | L24: =VLOOKUP(B24,ORG!J:K,2,FALSE) -> 2026 | P24: Brabo Globetrotters | Q24: A | R24: 19 | S24: B | T24: REBAIXADO | U24: 2025
A25: B | B25: Metamoney F.C | C25: 23 | D25: MARCIO GAI | E25: 69 | F25: 24 | G25: 1 | H25: 13 | I25: 3197.31 | J25: P | K25: B | L25: =VLOOKUP(B25,ORG!J:K,2,FALSE) -> 2026 | P25: Abóbora Futebol C | Q25: A | R25: 20 | S25: B | T25: REBAIXADO | U25: 2025
A26: B | B26: Silasbrs FC | C26: 24 | D26: SILINHAS | E26: 66 | F26: 23 | G26: 0 | H26: 15 | I26: 3221.26 | J26: P | K26: B | L26: =VLOOKUP(B26,ORG!J:K,2,FALSE) -> 2026 | P26: Sempre ForteF.C. | Q26: B | R26: 27 | S26: B | T26: FICOU NA SERIE | U26: 2025
A27: B | B27: Os Porko é Loko - Z/O | C27: 25 | D27: ANDERSON PORKO | E27: 63 | F27: 22 | G27: 0 | H27: 16 | I27: 3142.21 | J27: M | K27: B | L27: =VLOOKUP(B27,ORG!J:K,2,FALSE) -> 2026 | P27: Ferrugem Ultimate | Q27: B | R27: 28 | S27: B | T27: FICOU NA SERIE | U27: 2025
A28: B | B28: CRPELUSO | C28: 26 | D28: CLAUDIO PELUSO | E28: 60 | F28: 20 | G28: 0 | H28: 18 | I28: 3247.64 | J28: M | K28: B | L28: =VLOOKUP(B28,ORG!J:K,2,FALSE) -> 2026 | P28: 08 Ratto FC | Q28: B | R28: 29 | S28: B | T28: FICOU NA SERIE | U28: 2025
A29: B | B29: Sempre ForteF.C. | C29: 27 | D29: JONATHAN BATATA | E29: 60 | F29: 22 | G29: 0 | H29: 16 | I29: 3156.98 | J29: M | K29: B | L29: =VLOOKUP(B29,ORG!J:K,2,FALSE) -> 2026 | P29: GEJA | Q29: B | R29: 30 | S29: B | T29: FICOU NA SERIE | U29: 2025
A30: B | B30: Ferrugem Ultimate | C30: 28 | D30: THIAGO RIBAS | E30: 57 | F30: 20 | G30: 0 | H30: 18 | I30: 2895.37 | J30: M | K30: B | L30: =VLOOKUP(B30,ORG!J:K,2,FALSE) -> 2026 | P30: FUCKER AND SUCKER FC | Q30: B | R30: 32 | S30: B | T30: FICOU NA SERIE | U30: 2025
A31: B | B31: 08 Ratto FC | C31: 29 | D31: GABRIEL RATTO 1 | E31: 56 | F31: 20 | G31: 0 | H31: 18 | I31: 3250.32 | J31: M | K31: B | L31: =VLOOKUP(B31,ORG!J:K,2,FALSE) -> 2026 | P31: SC Ornaghi Paulista | Q31: B | R31: 33 | S31: B | T31: FICOU NA SERIE | U31: 2025
A32: B | B32: GEJA | C32: 30 | D32: WEDSON | E32: 54 | F32: 19 | G32: 0 | H32: 19 | I32: 3040.39 | J32: M | K32: B | L32: =VLOOKUP(B32,ORG!J:K,2,FALSE) -> 2026 | P32: Massiminismo FC | Q32: B | R32: 35 | S32: B | T32: FICOU NA SERIE | U32: 2025
A33: B | B33: SOROCITYSOCCER | C33: 31 | D33: ALEX TENIS MOURA | E33: 53 | F33: 19 | G33: 0 | H33: 19 | I33: 2959.86 | J33: M | K33: B | L33: =VLOOKUP(B33,ORG!J:K,2,FALSE) -> #N/A | P33: Bilao Sport Club | Q33: B | R33: 36 | S33: B | T33: FICOU NA SERIE | U33: 2025
A34: B | B34: FUCKER AND SUCKER FC | C34: 32 | D34: VERON | E34: 51 | F34: 18 | G34: 0 | H34: 20 | I34: 3105.52 | J34: M | K34: B | L34: =VLOOKUP(B34,ORG!J:K,2,FALSE) -> 2026 | P34: Botafogo Hell | Q34: C | R34: 41 | S34: B | T34: VAGA DIRETA | U34: 2025
... A41: B | B41: Almi Jr. FC | C41: 39 | D41: ALMI JUNIOR | E41: 32 | F41: 11 | G41: 0 | H41: 27 | I41: 2894.92 | J41: R | K41: B | L41: =VLOOKUP(B41,ORG!J:K,2,FALSE) -> 2026 | P41: Centenario Alviverde | Q41: C | R41: 50 | S41: B | T41: VAGA POR DESISTENCIA | U41: 2025
A42: B | B42: Caixão do Papaco | C42: 40 | D42: ADRIANO CUNHA EL LOUCO | E42: 31 | F42: 11 | G42: 0 | H42: 27 | I42: 2199.52 | J42: R | K42: B | P42: Gabirobense | Q42: B | R42: 37 | S42: C | T42: REBAIXADO | U42: 2025
P43: APELÕES FUTEBOL CLUB | Q43: B | R43: 38 | S43: C | T43: REBAIXADO | U43: 2025
A44: C | B44: Botafogo Hell | C44: 41 | D44: GABRIEL VUDU | E44: 77 | F44: 27 | G44: 1 | H44: 10 | I44: 3296.15 | J44: P | K44: C | L44: =VLOOKUP(B44,ORG!J:K,2,FALSE) -> 2026 | P44: Almi Jr. FC | Q44: B | R44: 39 | S44: C | T44: REBAIXADO | U44: 2025
A45: C | B45: Bike Cristo | C45: 42 | D45: MAURÍCIO VÉIO DA LARANJA | E45: 76 | F45: 27 | G45: 0 | H45: 11 | I45: 3268.83 | J45: P | K45: C | L45: =VLOOKUP(B45,ORG!J:K,2,FALSE) -> 2026 | P45: Borussia do Jaguaré | Q45: C | R45: 51 | S45: C | T45: FICOU NA SERIE | U45: 2025
A46: C | B46: J.V.Finhani | C46: 43 | D46: JEFFERSON FINHANI TI | E46: 75 | F46: 26 | G46: 0 | H46: 12 | I46: 3191.28 | J46: P | K46: C | L46: =VLOOKUP(B46,ORG!J:K,2,FALSE) -> 2026 | P46: Xuchélides | Q46: C | R46: 52 | S46: C | T46: FICOU NA SERIE | U46: 2025
...

Sheet GERAL 2025
A1: Ordem | B1: Jogador | C1: Time | D1: Pontos
A2: 74 | B2: ADRIANO CUNHA EL LOUCO | C2: Caixão do Papaco | D2: 2199.52
A3: 37 | B3: ADRIANO ZIZU | C3: Adriano ZIZU | D3: 3109.94
A4: 20 | B4: ADSON MENDES | C4: Adshow17 F.C | D4: 3222.62
A5: 56 | B5: ALEX TENIS MOURA | C5: SOROCITYSOCCER | D5: 2959.86
A6: 25 | B6: ALEXANDRE IPANEMA | C6: Ipanema13 | D6: 3190.84
A7: 44 | B7: ALLAN JAMES | C7: Centenario Alviverde | D7: 3080.53
A8: 33 | B8: ALLAN SANTOS | C8: #Santos.Z/O | D8: 3141.74
A9: 78 | B9: ALLEN | C9: Zona Leste Paulista | D9: 1689.29
A10: 62 | B10: ALMI JUNIOR | C10: Almi Jr. FC | D10: 2894.92
A11: 67 | B11: ALMIR RIMLAFC | C11: RIMLAFC | D11: 2752.76
A12: 16 | B12: ALYSON CALAZANS | C12: CalazansTeam | D12: 3244.03
A13: 32 | B13: ANDERSON PORKO | C13: Os Porko é Loko - Z/O | D13: 3142.21
... A62: 9 | B62: MAURÍCIO VÉIO DA LARANJA | C62: Bike Cristo | D62: 3268.83
A63: 63 | B63: MICHAEL REIS | C63: Kings Futebol Club | D63: 2893
A64: 70 | B64: OTAVIO DAMASCENO | C64: Timao do Otao | D64: 2536.86
A65: 53 | B65: PAULO OTO | C65: OtoPat@ma | D65: 2970.04
A66: 19 | B66: RICARDO FILGUEIRAS | C66: Amigos do Loco Abreu | D66: 3224.9
A67: 11 | B67: RICARDO MALETA | C67: Maletinhas F.C. | D67: 3262.38
A68: 57 | B68: RICARDO SHOJI | C68: Na Midola FC | D68: 2958.88
A69: 35 | B69: RICARDO TRIPAO | C69: ZEKABOLEIRO | D69: 3120.55
A70: 81 | B70: RICHARD MENEGUETI | C70: RMENEGHETTI | D70: 1487.35
A71: 36 | B71: ROBSON CUNHA | C71: RCUNHA S.C.C.P | D71: 3115.84
A72: 49 | B72: ROGÉRIO LAGOS | C72: Borussia da Pompeia | D72: 3051.13
A73: 48 | B73: SCHULAI 1 | C73: Schuletroll | D73: 3052.98
A74: 18 | B74: SERGIO GARCIA | C74: GIGANTES MORUMBI F.C | D74: 3235.59
A75: 21 | B75: SILINHAS | C75: Silasbrs FC | D75: 3221.26
... A80: 71 | B80: WELLIGTON ABOBORA | C80: Abóbora Futebol C | D80: 2472.85
A81: 66 | B81: WESLEY YORKS | C81: Yorks Gamora & Goku FC | D81: 2784
A82: 43 | B82: YURI ALLEJO | C82: Allejo Team F.C | D82: 3094.12

Sheet DUPLAS
A2: Bike Cristo
A3: Maurício Silva
A4: 107.66
A5: 1º
A6: Escalou
A7: Acessar o perfil do time Andico F.C
A9: Andico F.C
A10: Leandro Souza
A11: 103.98
A12: 2º
A13: Não Escalou
A14: Acessar o perfil do time F.C Felicio F.C
... A405: Não Escalou

Sheet Col Val D
B1: b2 | E1: b2 | G1: a | H1: b2
A2: CalazansTeam | B2: 1 | D2: FOI O QUE SOBROU | E2: 1 | G2: Bike Cristo | H2: 1
A3: ALYSON | B3: 2 | D3: V. ÉDIPO | E3: 2 | G3: Maurício Silva | H3: 2
A4: 136.77 | B4: 3 | D4: 119.98 | E4: 3 | G4: 107.66 | H4: 3
A5: 1º | B5: 4 | D5: 1º | E5: 4 | G5: 1º | H5: 4
A6: Escalou | B6: 5 | D6: Não Escalou | E6: 5 | G6: Escalou | H6: 5
A7: Acessar o perfil do time Parrudo'S Team | B7: 6 | D7: Acessar o perfil do time Mariliense F.C | E7: 6 | G7: Acessar o perfil do time Andico F.C | H7: 6
B8: 7 | E8: 7 | H8: 7
A9: Parrudo'S Team | B9: 1 | D9: Mariliense F.C | E9: 1 | G9: Andico F.C | H9: 1
A10: Diego Longo | B10: 2 | D10: Nick | E10: 2 | G10: Leandro Souza | H10: 2
A11: 128.61 | B11: 3 | D11: 109.08 | E11: 3 | G11: 103.98 | H11: 3
A12: 2º | B12: 4 | D12: 2º | E12: 4 | G12: 2º | H12: 4
A13: Não Escalou | B13: 5 | D13: Não Escalou | E13: 5 | G13: Não Escalou | H13: 5
A14: Acessar o perfil do time GIGANTES MORUMBI F.C | B14: 6 | D14: Acessar o perfil do time DEIZÃO FUTEBOL CLUBE | E14: 6 | G14: Acessar o perfil do time F.C Felicio F.C | H14: 6
B15: 7 | E15: 7 | H15: 7
A16: GIGANTES MORUMBI F.C | B16: 1 | D16: DEIZÃO FUTEBOL CLUBE | E16: 1 | G16: F.C Felicio F.C | H16: 1
A17: Sergio Garcia | B17: 2 | D17: CAMISA . 10 | E17: 2 | G17: Guilherme Felicio | H17: 2
A18: 127.81 | B18: 3 | D18: 107.68 | E18: 3 | G18: 102.69 | H18: 3
A19: 3º | B19: 4 | D19: 3º | E19: 4 | G19: 3º | H19: 4
A20: Escalou | B20: 5 | D20: Não Escalou | E20: 5 | G20: Não Escalou | H20: 5
A21: Acessar o perfil do time PALM£IRAS S.E.P. | B21: 6 | D21: Acessar o perfil do time Mitinga`s F.C | E21: 6 | G21: Acessar o perfil do time Pelicano Papada F.C | H21: 6
B22: 7 | E22: 7 | H22: 7
A23: PALM£IRAS S.E.P. | B23: 1 | D23: Mitinga`s F.C | E23: 1 | G23: Pelicano Papada F.C | H23: 1
A24: Diego Longo | B24: 2 | D24: Marcel Cantalego | E24: 2 | G24: Leandro Schulai | H24: 2
A25: 124.61 | B25: 3 | D25: 106.98 | E25: 3 | G25: 95.31 | H25: 3
A26: 4º | B26: 4 | D26: 4º | E26: 4 | G26: 4º | H26: 4
A27: Escalou | B27: 5 | D27: Não Escalou | E27: 5 | G27: Não Escalou | H27: 5
A28: Acessar o perfil do time Maletinhas F.C. | B28: 6 | D28: Acessar o perfil do time PALM£IRAS S.E.P. | E28: 6 | G28: Acessar o perfil do time GIGANTES MORUMBI F.C | H28: 6
B29: 7 | E29: 7 | H29: 7
A30: Maletinhas F.C. | B30: 1 | D30: PALM£IRAS S.E.P. | E30: 1 | G30: GIGANTES MORUMBI F.C | H30: 1
A31: Ricardo | B31: 2 | D31: Diego Longo | E31: 2 | G31: Sergio Garcia | H31: 2
A32: 124.51 | B32: 3 | D32: 106.88 | E32: 3 | G32: 92.66 | H32: 3
A33: 5º | B33: 4 | D33: 5º | E33: 4 | G33: 5º | H33: 4
A34: Não Escalou | B34: 5 | D34: Escalou | E34: 5 | G34: Não Escalou | H34: 5
A35: Acessar o perfil do time Marco-FSA | B35: 6 | D35: Acessar o perfil do time Wedgol | E35: 6 | G35: Acessar o perfil do time Luket Wanderes fc | H35: 6
B36: 7 | E36: 7 | H36: 7
A37: Marco-FSA | B37: 1 | D37: Wedgol | E37: 1 | G37: Luket Wanderes fc | H37: 1
A38: MarcoCzDutra | B38: 2 | D38: Wedson da Silva | E38: 2 | G38: Lucas Silva Vieira | H38: 2
A39: 124.29 | B39: 3 | D39: 106.38 | E39: 3 | G39: 92.28 | H39: 3
A40: 6º | B40: 4 | D40: 6º | E40: 4 | G40: 6º | H40: 4
...

Sheet Colagem D
A1: Gabirobense | B1: 109.35 | D1: Xuchélides | E1: 92.81 | G1: nascimento124 | H1: 102.26 | J1: CalazansTeam | K1: 136.77 | M1: FOI O QUE SOBROU | N1: 119.98 | P1: Bike Cristo | Q1: 107.66
A2: GEJA | B2: 107.65 | D2: Grajaux City F.C. | E2: 92.41 | G2: Juquitas FC | H2: 99.86 | J2: Parrudo'S Team | K2: 128.61 | M2: Mariliense F.C | N2: 109.08 | P2: Andico F.C | Q2: 103.98
A3: Almi Jr. FC | B3: 103.65 | D3: Tua Mãe SEP | E3: 91.21 | G3: Sobottka FC 633 | H3: 99.82 | J3: GIGANTES MORUMBI F.C | K3: 127.81 | M3: DEIZÃO FUTEBOL CLUBE | N3: 107.68 | P3: F.C Felicio F.C | Q3: 102.69
A4: Mosby | B4: 100.75 | D4: Allejo Team F.C | E4: 89.40 | G4: Silasbrs FC | H4: 98.52 | J4: PALM£IRAS S.E.P. | K4: 124.61 | M4: Mitinga`s F.C | N4: 106.98 | P4: Pelicano Papada F.C | Q4: 95.31
A5: Mitinga`s F.C | B5: 96.85 | D5: A D Peaky Blinders | E5: 86.90 | G5: Luket Wanderes fc | H5: 98.32 | J5: Maletinhas F.C. | K5: 124.51 | M5: PALM£IRAS S.E.P. | N5: 106.88 | P5: GIGANTES MORUMBI F.C | Q5: 92.66
A6: Allejo Team F.C | B6: 96.55 | D6: Sobottka FC 633 | E6: 85.90 | G6: Al Ahly Ecc | H6: 98.32 | J6: Marco-FSA | K6: 124.29 | M6: Wedgol | N6: 106.38 | P6: Luket Wanderes fc | Q6: 92.28
A7: Ipanema13 | B7: 96.55 | D7: Luket Wanderes fc | E7: 82.99 | G7: Mitinga`s F.C | H7: 96.32 | J7: Luket Wanderes fc | K7: 123.81 | M7: Miss Procon Futebol Clube | N7: 106.28 | P7: Al Ahly Ecc | Q7: 92.28
A8: Parrudo'S Team | B8: 96.55 | D8: Al Ahly Ecc | E8: 82.99 | G8: SAY ZIKA | H8: 95.82 | J8: Al Ahly Ecc | K8: 123.81 | M8: Machadotti1972 | N8: 105.88 | P8: Wedgol | Q8: 92.15
A9: Silasbrs FC | B9: 96.26 | D9: Sanlutty FC | E9: 82.90 | G9: Olimpingas Sport Club | H9: 95.02 | J9: Grajaux City F.C. | K9: 121.69 | M9: CalazansTeam | N9: 105.38 | P9: Sanlutty FC | Q9: 91.86
A10: SAY ZIKA | B10: 95.55 | D10: Machadotti1972 | E10: 81.39 | G10: SÓRRESTO | H10: 94.72 | J10: Brabo Globetrotters | K10: 121.47 | M10: J.V.Finhani | N10: 104.99 | P10: PALM£IRAS S.E.P. | Q10: 91.16
A11: Sobottka FC 633 | B11: 94.86 | D11: Mala03Fc | E11: 78.89 | G11: Mariliense F.C | H11: 93.72 | J11: Almi Jr. FC | K11: 121.01 | M11: Ipanema13 | N11: 104.58 | P11: Ipanema13 | Q11: 90.06
A12: Mariliense F.C | B12: 92.66 | D12: Botafogo Hell | E12: 78.69 | G12: Allejo Team F.C | H12: 93.32 | J12: Diniz Santastico1 | K12: 120.09 | M12: Andico F.C | N12: 104.38 | P12: Olimpingas Sport Club | Q12: 90.06
... A58: DIDIBRE FC | B58: 48.79 | D58: Adshow17 F.C | E58: 26.04 | G58: DIDIBRE FC | H58: 43.36 | J58: DIDIBRE FC | K58: 28.46 | M58: DIDIBRE FC | N58: 32.03 | P58: DIDIBRE FC | Q58: 26.05

Sheet base_2026_D
A1: Dupla | B1: Nome Cartoleiro 1 | C1: Time Cartoleiro 1 | D1: Dupla | F1: time | G1: Nome | I1: Nome | M1: id | N1: ano | P1: POS | Q1: TIME 1 | R1: id1 | S1: TIME 2 | T1: id2 | U1: PT1 | V1: PT2 | W1: TOTA ROD1
A2: 1 | B2: Elza Gadelha Quirino | C2: Miss Procon Futebol Clube | D2: Daniel Quirino | F2: CalazansTeam | G2: A CALAZANS | H2: =VLOOKUP(G2,J:K,2,FALSE) -> 1 | I2: CalazansTeam | J2: A CALAZANS | K2: 1 | M2: 1 | N2: 2026 | P2: 1º | Q2: Didibre FC | R2: 14 | S2: nascimento124 | T2: 40 | U2: 90.05 | V2: 70.26 | W2: =SUM(U2:V2) -> 160.31
A3: 1 | B3: Daniel Quirino | C3: Olimpingas Sport Club | D3: Elza Gadelha Quirino | F3: Mariliense F.C | G3: A CARLOS | H3: =VLOOKUP(G3,J:K,2,FALSE) -> 2 | I3: Mariliense F.C | J3: A CARLOS | K3: 2 | M3: 2 | N3: 2026 | P3: 2º | Q3: Na Midola FC | R3: 39 | S3: Mosby | T3: 38 | U3: 94.26 | V3: 60.26 | W3: =SUM(U3:V3) -> 154.52
A4: 2 | B4: Wedson | C4: GEJA | D4: Wedgol | F4: Adshow17 F.C | G4: ADSON | H4: =VLOOKUP(G4,J:K,2,FALSE) -> 3 | I4: Adshow17 F.C | J4: ADSON | K4: 3 | M4: 3 | N4: 2026 | P4: 3º | Q4: Machadotti1972 | R4: 30 | S4: Realmengo07 Fc | T4: 46 | U4: 74.96 | V4: 74.96 | W4: =SUM(U4:V4) -> 149.92
A5: 2 | B5: Wedson | C5: Wedgol | D5: GEJA | F5: Ipanema13 | G5: ALE CHINELO | H5: =VLOOKUP(G5,J:K,2,FALSE) -> 4 | I5: Ipanema13 | J5: ALE CHINELO | K5: 4 | M5: 4 | N5: 2026 | P5: 4º | Q5: Massiminismo FC | R5: 35 | S5: Real Rattaria FC | T5: 45 | U5: 68.96 | V5: 78.46 | W5: =SUM(U5:V5) -> 147.42
A6: 3 | B6: Adson Mendes | C6: Adshow 17 | D6: Sobottka FC 633 | F6: Almi Jr. FC | G6: ALMI | H6: =VLOOKUP(G6,J:K,2,FALSE) -> 5 | I6: Almi Jr. FC | J6: ALMI | K6: 5 | M6: 5 | N6: 2026 | P6: 5º | Q6: GEJA | R6: 21 | S6: Wedgol | T6: 57 | U6: 69.1 | V6: 74.7 | W6: =SUM(U6:V6) -> 143.8
A7: 3 | B7: Gustavo Nery | C7: Sobottka FC 633 | D7: Adshow 17 | F7: Andico F.C | G7: ANDICO | H7: =VLOOKUP(G7,J:K,2,FALSE) -> 6 | I7: Andico F.C | J7: ANDICO | K7: 6 | M7: 6 | N7: 2026 | P7: 6º | Q7: Botafogo Hell | R7: 9 | S7: Hpano FC | T7: 24 | U7: 63.5 | V7: 78.7 | W7: =SUM(U7:V7) -> 142.2
A8: 4 | B8: Maurício Véio da Laranja | C8: Bike Cristo | D8: Real Sarandi Clube | F8: mala03fc | G8: B DUCATI | H8: =VLOOKUP(G8,J:K,2,FALSE) -> 7 | I8: mala03fc | J8: B DUCATI | K8: 7 | M8: 7 | N8: 2026 | P8: 7º | Q8: CalazansTeam | R8: 12 | S8: J.V.Finhani | T8: 26 | U8: 66.86 | V8: 68.4 | W8: =SUM(U8:V8) -> 135.26
A9: 4 | B9: André Prates 1 | C9: Zago Pratis | D9: Bike Cristo | F9: Brabo Globetrotters | G9: BRABO | H9: =VLOOKUP(G9,J:K,2,FALSE) -> 8 | I9: Brabo Globetrotters | J9: BRABO | K9: 8 | M9: 8 | N9: 2026 | P9: 8º | Q9: Andico F.C | R9: 7 | S9: Burza F C | T9: 11 | U9: 65.4 | V9: 69.5 | W9: =SUM(U9:V9) -> 134.9
A10: 5 | B10: Lucas Massimini | C10: Massiminismo FC | D10: Real Rattaria FC | F10: Burza F C | G10: BURZA | H10: =VLOOKUP(G10,J:K,2,FALSE) -> 9 | I10: Burza F C | J10: BURZA | K10: 9 | M10: 9 | N10: 2026 | P10: 9º | Q10: Joga Tranquilo F.S. | R10: 27 | S10: SAY ZIKA | T10: 48 | U10: 74.2 | V10: 57.36 | W10: =SUM(U10:V10) -> 131.56
A11: 5 | B11: Gabriel Ratto 2 | C11: Real Rattaria FC | D11: Massiminismo FC | F11: Xuchélides | G11: C TEIXEIRA | H11: =VLOOKUP(G11,J:K,2,FALSE) -> 10 | I11: Xuchélides | J11: C TEIXEIRA | K11: 10 | M11: 10 | N11: 2026 | P11: 10º | Q11: Brabo Globetrotters | R11: 10 | S11: A D Peaky Blinders | T11: 2 | U11: 56.46 | V11: 73.8 | W11: =SUM(U11:V11) -> 130.26
A12: 6 | B12: Alyson Calazans | C12: CalazansTeam | D12: J.V.Finhani | F12: Grajaux City F.C. | G12: D FERREIRA | H12: =VLOOKUP(G12,J:K,2,FALSE) -> 11 | I12: Grajaux City F.C. | J12: D FERREIRA | K12: 11 | M12: 11 | N12: 2026 | P12: 11º | Q12: Adshow17 F.C | R12: 3 | S12: Sobottka FC 633 | T12: 52 | U12: 62.16 | V12: 66.8 | W12: =SUM(U12:V12) -> 128.96
A13: 6 | B13: Jefferson Finhani TI | C13: J.V.Finhani | D13: CalazansTeam | F13: Tupinianos FC | G13: D FERREIRA | H13: =VLOOKUP(G13,J:K,2,FALSE) -> 11 | I13: Tupinianos FC | J13: D LONGO | K13: 12 | M13: 12 | N13: 2026 | P13: 12º | Q13: Ipanema13 | R13: 25 | S13: Mariliense F.C | T13: 34 | U13: 64.46 | V13: 64.46 | W13: =SUM(U13:V13) -> 128.92
... A33: 16 | B33: Lucat | C33: Luket Wanderes fc | D33: E.C. Ocram 5.5 | F33: J.V.Finhani | G33: J FINHANI | H33: =VLOOKUP(G33,J:K,2,FALSE) -> 30 | I33: J.V.Finhani | J33: L MASSIMINI | K33: 32 | M33: 32 | N33: 2026 | P33: 32º | Q33: Gigantes Morumbi F.C | R33: 22 | S33: TIMAO R.F.G | T33: 54 | U33: 39.26 | V33: 50.56 | W33: =SUM(U33:V33) -> 89.82
A34: 17 | B34: Lucat | C34: Al Ahly Ecc | D34: Pelicano Papada | F34: A D Peaky Blinders | G34: KAJURU | H34: =VLOOKUP(G34,J:K,2,FALSE) -> 31 | I34: A D Peaky Blinders | J34: LUCAT | K34: 33 | M34: 33 | N34: 2026
A35: 17 | B35: Leandro Schulai 3 | C35: Pelicano Papada | D35: Luket Wanderes fc | F35: Massiminismo FC | G35: L MASSIMINI | H35: =VLOOKUP(G35,J:K,2,FALSE) -> 32 | I35: Massiminismo FC | J35: LUKET | K35: 34 | M35: 34 | N35: 2026
A36: 18 | B36: Thiago Ribas | C36: Ferrugem Ultimate | D36: Marco-FSA | F36: Al Ahly Ecc | G36: LUCAT | H36: =VLOOKUP(G36,J:K,2,FALSE) -> 33 | I36: Al Ahly Ecc | J36: LUTTY | K36: 35 | M36: 35 | N36: 2026
A37: 18 | B37: Marco Amigo Thiago Ribas | C37: Marco-FSA | D37: Thiago Ribas | F37: Luket Wanderes fc | G37: LUKET | H37: =VLOOKUP(G37,J:K,2,FALSE) -> 34 | I37: Luket Wanderes fc | J37: M CANTALEGO | K37: 36 | M37: 36 | N37: 2026
A38: 19 | B38: Eduardo Ornaghi | C38: SC Ornaghi Paulista | D38: Real Sarandi Clube | F38: Sanlutty FC | G38: LUTTY | H38: =VLOOKUP(G38,J:K,2,FALSE) -> 35 | I38: Sanlutty FC | J38: M COIMBRA | K38: 37 | M38: 37 | N38: 2026
A39: 19 | B39: André Prates 2 | C39: Zago Pratis | D39: SC Ornaghi Paulista | F39: Mitinga`s F.C | G39: M CANTALEGO | H39: =VLOOKUP(G39,J:K,2,FALSE) -> 36 | I39: Mitinga`s F.C | J39: M OCRAM | K39: 38 | M39: 38 | N39: 2026
A40: 20 | B40: Marcel Cantalego | C40: Mitinga's F.C | D40: Silasbrs FC | F40: Realmengo07 Fc | G40: M COIMBRA | H40: =VLOOKUP(G40,J:K,2,FALSE) -> 37 | I40: Realmengo07 Fc | J40: ORNAGHI | K40: 39 | M40: 39 | N40: 2026
A41: 20 | B41: Silas | C41: Silasbrs FC | D41: Mitinga's F.C | F41: E.C. Ocram 5.6 | G41: M OCRAM | H41: =VLOOKUP(G41,J:K,2,FALSE) -> 38 | I41: E.C. Ocram 5.6 | J41: PRATIS | K41: 40 | M41: 40 | N41: 2026
A42: 21 | B42: Alexandre Carlos | C42: Ipanema 13 | D42: Mariliense | F42: SC Ornaghi Paulista | G42: ORNAGHI | H42: =VLOOKUP(G42,J:K,2,FALSE) -> 39 | I42: SC Ornaghi Paulista | J42: R CUNHA | K42: 41 | M42: 41 | N42: 2026
A43: 21 | B43: Alexandre Carlos | C43: Mariliense | D43: Ipanema 13 | F43: ZAGO PRATIS FC | G43: PRATIS | H43: =VLOOKUP(G43,J:K,2,FALSE) -> 40 | I43: ZAGO PRATIS FC | J43: R MALETA | K43: 42 | M43: 42 | N43: 2026
A44: 22 | B44: Andico | C44: Andico F.C | D44: Burza | F44: TIMAO R.F.G | G44: R CUNHA | H44: =VLOOKUP(G44,J:K,2,FALSE) -> 41 | I44: TIMAO R.F.G | J44: R SHOJI | K44: 43 | M44: 43 | N44: 2026
A45: 22 | B45: Burza | C45: Burza FC | D45: Andico | F45: Maletinhas F.C. | G45: R MALETA | H45: =VLOOKUP(G45,J:K,2,FALSE) -> 42 | I45: Maletinhas F.C. | J45: R TRIPAO | K45: 44 | M45: 44 | N45: 2026
... A53: 26 | B53: Enzo Nascimento | C53: Nascimento 124 | D53: Diego Valadares | F53: Schuletroll | G53: SCHULETA | H53: =VLOOKUP(G53,J:K,2,FALSE) -> 47 | I53: Schuletroll | J53: Y ALLEJO | K53: 52 | M53: 52 | N53: 2026
A54: 27 | B54: Guilherme Felicio | C54: F.C Felicio F.C | D54: Giovanni Castro | F54: Ferrugem Ultimate | G54: T RIBAS | H54: =VLOOKUP(G54,J:K,2,FALSE) -> 48 | I54: Ferrugem Ultimate | M54: 53 | N54: 2026
A55: 27 | B55: Giovanni Castro | C55: Tua mãe SEP | D55: Guilherme Felicio | F55: Marco-FSA | G55: T RIBAS | H55: =VLOOKUP(G55,J:K,2,FALSE) -> 48 | I55: Marco-FSA | M55: 54 | N55: 2026
A56: 29 | B56: Yuri Oliveira | C56: Allejo Team F.C | D56: William Pereira | F56: Bike Cristo | G56: VEIO DA LARANJA | H56: =VLOOKUP(G56,J:K,2,FALSE) -> 49 | I56: Bike Cristo | M56: 55 | N56: 2026
A57: 29 | B57: William Pereira | C57: Juquitas FC | D57: Yuri Oliveira | F57: Juquitas FC | G57: W SILVA | H57: =VLOOKUP(G57,J:K,2,FALSE) -> 50 | I57: Juquitas FC | M57: 56 | N57: 2026
A58: 30 | B58: Ricardo Shoji | C58: Na Midola FC | D58: Mosby 1 | F58: GEJA | G58: WED | H58: =VLOOKUP(G58,J:K,2,FALSE) -> 51 | I58: GEJA | M58: 57 | N58: 2026
A59: 30 | B59: Felipe Mosby | C59: Mosby | D59: Shoju | F59: Wedgol | G59: WED | H59: =VLOOKUP(G59,J:K,2,FALSE) -> 51 | I59: Wedgol | M59: 58 | N59: 2026
A60: 31 | B60: Maletas | C60: Maletinhas F.C. | D60: Robson 2 | F60: Allejo Team F.C | G60: Y ALLEJO | H60: =VLOOKUP(G60,J:K,2,FALSE) -> 52 | I60: Allejo Team F.C | M60: 59 | N60: 2026
A61: 31 | B61: Robson 2 | C61: Deizão Futebol Clube | D61: Maletinhas
A62: 32 | B62: Eduardo Ornaghi 2 | C62: SC Ornaghi Paulista | D62: Maurício Véio da Laranja 2
A63: 32 | B63: Maurício Véio da Laranja 2 | C63: Bike Cristo | D63: Eduardo Ornaghi 2
A64: 33 | C64: Brabo Globetrotters
A65: 33 | C65: A D Peaky Blinders

Sheet Planilha6
A1: id | B1: cartoleiro_id | C1: nome | D1: id | F1: Didibre FC | G1: =VLOOKUP(F1,C:D,2,FALSE) -> 16 | I1: 1 | K1: nascimento124 | L1: =VLOOKUP(K1,C:D,2,FALSE) -> 20 | N1: 1 | O1: 20 | P1: 2026 | Q1: O Nascimento do Dibre | R1: 1 | T1: id | U1: ano | V1: nome
A2: 1 | B2: 1 | C2: CalazansTeam | D2: 1 | F2: Na Midola FC | G2: =VLOOKUP(F2,C:D,2,FALSE) -> 45 | I2: 2 | K2: Mosby | L2: =VLOOKUP(K2,C:D,2,FALSE) -> 22 | N2: 2 | O2: 22 | P2: 2026 | Q2: Mosby na Midola | R2: 2 | T2: 1 | U2: 2026 | V2: O Nascimento do Dibre
